Workbook

Sheet TO 1
A3: REKAPITULASI HASIL ASSESMENT
A4: SMK AL MUSYAFFA' KENDAL
A5: KELAS X TO 1
A7: NO | B7: NAMA LENGKAP | C7: IQ | D7: K35AEPLIN | G7: EPP65
D8: 1 | E8: 2 | F8: 3 | G8: 1 | H8: 2 | I8: 3 | J8: 4 | K8: 5 | L8: 6 | M8: 7 | N8: 8 | O8: 9 | P8: 10 | Q8: 11 | R8: 12 | S8: 13 | T8: 14 | U8: 15 | V8: 16
A9: 1 | B9: AHMAD FARIZQI RIDWAN | C9: 115 | D9: 35 | E9: 35 | F9: 35 | G9: 7 | H9: 11 | I9: 12 | J9: 15 | K9: 12 | L9: 9 | M9: 16 | N9: 12 | O9: 13 | P9: 10 | Q9: 16 | R9: 9 | S9: 14 | T9: 17 | U9: 11 | V9: 16
A10: 2 | B10: AHMAD IDRIS SIREGAR | C10: 85 | D10: 35 | E10: 35 | F10: 35 | G10: 5 | H10: 13 | I10: 10 | J10: 11 | K10: 14 | L10: 11 | M10: 16 | N10: 21 | O10: 11 | P10: 13 | Q10: 12 | R10: 9 | S10: 16 | T10: 13 | U10: 11 | V10: 13
A11: 3 | B11: AHMAD IRFAN | C11: 105 | D11: 35 | E11: 35 | F11: 35 | G11: 10 | H11: 14 | I11: 11 | J11: 15 | K11: 13 | L11: 12 | M11: 10 | N11: 17 | O11: 9 | P11: 13 | Q11: 10 | R11: 11 | S11: 12 | T11: 12 | U11: 18 | V11: 18
A12: 4 | B12: ALIF BUDI FIRMANSYAH | C12: 80 | D12: 35 | E12: 80 | F12: 35 | G12: 9 | H12: 10 | I12: 13 | J12: 12 | K12: 15 | L12: 12 | M12: 14 | N12: 18 | O12: 14 | P12: 16 | Q12: 13 | R12: 11 | S12: 15 | T12: 8 | U12: 11 | V12: 15
A13: 5 | B13: AURA IDRIS AL QODRI | C13: 123 | D13: 35 | E13: 35 | F13: 35 | G13: 8 | H13: 9 | I13: 11 | J13: 12 | K13: 11 | L13: 13 | M13: 18 | N13: 16 | O13: 18 | P13: 13 | Q13: 12 | R13: 15 | S13: 13 | T13: 12 | U13: 10 | V13: 12
A14: 6 | B14: BAYU SAPUTRA | C14: 80 | D14: 35 | E14: 80 | F14: 65 | G14: 5 | H14: 12 | I14: 12 | J14: 14 | K14: 15 | L14: 9 | M14: 13 | N14: 17 | O14: 8 | P14: 14 | Q14: 16 | R14: 12 | S14: 14 | T14: 13 | U14: 11 | V14: 13
A15: 7 | B15: BIMBIM OCTA RAMADHANI | C15: 119 | D15: 35 | E15: 35 | F15: 35 | G15: 9 | H15: 8 | I15: 8 | J15: 9 | K15: 12 | L15: 14 | M15: 11 | N15: 16 | O15: 22 | P15: 10 | Q15: 17 | R15: 14 | S15: 9 | T15: 14 | U15: 15 | V15: 12
A16: 8 | B16: DAVIN AHMAD CHOIRUL YAQIN | C16: 80 | D16: 35 | E16: 80 | F16: 35 | G16: 8 | H16: 12 | I16: 8 | J16: 12 | K16: 10 | L16: 12 | M16: 14 | N16: 13 | O16: 17 | P16: 11 | Q16: 16 | R16: 9 | S16: 14 | T16: 17 | U16: 16 | V16: 12
A17: 9 | B17: ERNEST GERALDINE ARIANCA MAULANA | C17: 125 | D17: 35 | E17: 80 | F17: 35 | G17: 10 | H17: 18 | I17: 7 | J17: 10 | K17: 7 | L17: 10 | M17: 13 | N17: 11 | O17: 15 | P17: 6 | Q17: 20 | R17: 22 | S17: 11 | T17: 23 | U17: 11 | V17: 7
A18: 10 | B18: FARIS NAUFAL NURDIANSYAH | C18: 125 | D18: 65 | E18: 80 | F18: 80 | G18: 6 | H18: 9 | I18: 13 | J18: 16 | K18: 9 | L18: 14 | M18: 13 | N18: 13 | O18: 13 | P18: 16 | Q18: 15 | R18: 15 | S18: 12 | T18: 15 | U18: 10 | V18: 13
A19: 11 | B19: HAIKAL ABDUL GHOFUR | C19: 130 | D19: 35 | E19: 80 | F19: 35 | G19: 8 | H19: 13 | I19: 11 | J19: 14 | K19: 9 | L19: 11 | M19: 18 | N19: 11 | O19: 19 | P19: 12 | Q19: 14 | R19: 12 | S19: 13 | T19: 13 | U19: 16 | V19: 8
A20: 12 | B20: IKMAL MU'IN | C20: 90 | D20: 35 | E20: 80 | F20: 35 | G20: 9 | H20: 13 | I20: 9 | J20: 15 | K20: 13 | L20: 13 | M20: 16 | N20: 11 | O20: 12 | P20: 17 | Q20: 14 | R20: 13 | S20: 8 | T20: 17 | U20: 9 | V20: 16
... A23: 15 | B23: M. HUMAIDULLOH IRFAN | C23: 90 | D23: 35 | E23: 35 | F23: 35 | G23: 11 | H23: 16 | I23: 10 | J23: 13 | K23: 9 | L23: 10 | M23: 12 | N23: 14 | O23: 19 | P23: 14 | Q23: 12 | R23: 18 | S23: 13 | T23: 20 | U23: 9 | V23: 5
A24: 16 | B24: M. SAHRIEL SAPUTRA
A25: 17 | B25: M. WILDAN MUBAROK | C25: 115 | D25: 35 | E25: 35 | F25: 35 | G25: 10 | H25: 10 | I25: 16 | J25: 10 | K25: 10 | L25: 14 | M25: 16 | N25: 9 | O25: 12 | P25: 15 | Q25: 18 | R25: 9 | S25: 9 | T25: 17 | U25: 15 | V25: 13
A26: 18 | B26: MARTHA RIVAN ALFARIZ | C26: 80 | D26: 35 | E26: 35 | F26: 35 | G26: 11 | H26: 17 | I26: 9 | J26: 14 | K26: 16 | L26: 6 | M26: 14 | N26: 12 | O26: 20 | P26: 10 | Q26: 13 | R26: 16 | S26: 19 | T26: 17 | U26: 3 | V26: 9
A27: 19 | B27: MOHAMAD ALFARIJI | C27: 109 | D27: 35 | E27: 35 | F27: 65 | G27: 12 | H27: 13 | I27: 7 | J27: 6 | K27: 14 | L27: 13 | M27: 15 | N27: 14 | O27: 13 | P27: 10 | Q27: 17 | R27: 22 | S27: 10 | T27: 15 | U27: 8 | V27: 16
A28: 20 | B28: MUH. ILHAM FEBRIANSYAH | C28: 89 | D28: 35 | E28: 80 | F28: 35 | G28: 11 | H28: 15 | I28: 10 | J28: 15 | K28: 14 | L28: 10 | M28: 13 | N28: 11 | O28: 15 | P28: 11 | Q28: 14 | R28: 14 | S28: 11 | T28: 13 | U28: 14 | V28: 15
A29: 21 | B29: MUHAMAD ALYAMARI | C29: 110 | D29: 35 | E29: 80 | F29: 35 | G29: 11 | H29: 10 | I29: 10 | J29: 12 | K29: 10 | L29: 12 | M29: 17 | N29: 20 | O29: 17 | P29: 14 | Q29: 18 | R29: 15 | S29: 8 | T29: 16 | U29: 6 | V29: 11
A30: 22 | B30: MUHAMMAD AFFAN FANNANI | C30: 119 | D30: 35 | E30: 35 | F30: 35 | G30: 10 | H30: 15 | I30: 10 | J30: 5 | K30: 13 | L30: 16 | M30: 11 | N30: 13 | O30: 22 | P30: 10 | Q30: 17 | R30: 14 | S30: 13 | T30: 14 | U30: 12 | V30: 10
A31: 23 | B31: MUHAMMAD BAGUS TRIWARSITO | C31: 130 | D31: 35 | E31: 65 | F31: 35 | G31: 10 | H31: 16 | I31: 11 | J31: 10 | K31: 15 | L31: 8 | M31: 13 | N31: 21 | O31: 18 | P31: 11 | Q31: 16 | R31: 12 | S31: 12 | T31: 12 | U31: 7 | V31: 13
A32: 24 | B32: MUHAMMAD DZAKY HAIDAR DAFFA | C32: 85 | D32: 35 | E32: 35 | F32: 35 | G32: 10 | H32: 12 | I32: 4 | J32: 8 | K32: 12 | L32: 11 | M32: 15 | N32: 11 | O32: 22 | P32: 10 | Q32: 25 | R32: 19 | S32: 10 | T32: 14 | U32: 9 | V32: 14
A33: 25 | B33: MUHAMMAD HANIFIL ANAM
A34: 26 | B34: MUHAMMAD IRZAM FAIRUS SAPUTRA | C34: 85 | D34: 35 | E34: 80 | F34: 35 | G34: 7 | H34: 11 | I34: 12 | J34: 15 | K34: 13 | L34: 14 | M34: 9 | N34: 16 | O34: 13 | P34: 16 | Q34: 14 | R34: 10 | S34: 12 | T34: 14 | U34: 14 | V34: 13
A35: 27 | B35: MUHAMMAD RIFQI WIDIANTO | C35: 80 | D35: 35 | E35: 35 | F35: 35 | G35: 7 | H35: 14 | I35: 11 | J35: 9 | K35: 13 | L35: 8 | M35: 13 | N35: 13 | O35: 16 | P35: 15 | Q35: 14 | R35: 15 | S35: 15 | T35: 16 | U35: 10 | V35: 13
A36: 28 | B36: MUHAMMAD SEPTIANO RIZKY RAMADHAN | C36: 109 | D36: 35 | E36: 80 | F36: 35 | G36: 9 | H36: 8 | I36: 8 | J36: 13 | K36: 11 | L36: 11 | M36: 12 | N36: 18 | O36: 13 | P36: 17 | Q36: 16 | R36: 10 | S36: 10 | T36: 15 | U36: 16 | V36: 16
A37: 29 | B37: MUKHAMMAD ADIB | C37: 105 | D37: 35 | E37: 80 | F37: 65 | G37: 6 | H37: 8 | I37: 11 | J37: 12 | K37: 11 | L37: 15 | M37: 12 | N37: 13 | O37: 14 | P37: 15 | Q37: 15 | R37: 7 | S37: 17 | T37: 13 | U37: 18 | V37: 14
A38: 30 | B38: RYAN HIDAYAT | C38: 80 | D38: 35 | E38: 80 | F38: 35 | G38: 9 | H38: 11 | I38: 12 | J38: 15 | K38: 12 | L38: 9 | M38: 16 | N38: 12 | O38: 13 | P38: 10 | Q38: 16 | R38: 9 | S38: 14 | T38: 17 | U38: 11 | V38: 16
A39: 31 | B39: YUDA BAGUS | C39: 80 | D39: 35 | E39: 35 | F39: 35 | G39: 5 | H39: 14 | I39: 10 | J39: 10 | K39: 15 | L39: 9 | M39: 15 | N39: 17 | O39: 13 | P39: 14 | Q39: 11 | R39: 8 | S39: 11 | T39: 17 | U39: 15 | V39: 13

Sheet TO 2
A3: REKAPITULASI HASIL ASSESMENT
A4: SMK AL MUSYAFFA' KENDAL
A5: KELAS X TO 2
A7: NO | B7: NAMA LENGKAP | C7: IQ | D7: K35AEPLIN | G7: EPPS
D8: 1 | E8: 2 | F8: 3 | G8: 1 | H8: 2 | I8: 3 | J8: 4 | K8: 5 | L8: 6 | M8: 7 | N8: 8 | O8: 9 | P8: 10 | Q8: 11 | R8: 12 | S8: 13 | T8: 14 | U8: 15 | V8: 16
A9: 1 | B9: ADIT AIMANUN KHAK | C9: 80 | D9: 35 | E9: 35 | F9: 35 | G9: 8 | H9: 12 | I9: 8 | J9: 9 | K9: 13 | L9: 17 | M9: 14 | N9: 16 | O9: 10 | P9: 13 | Q9: 13 | R9: 10 | S9: 13 | T9: 14 | U9: 10 | V9: 16
A10: 2 | B10: AGUSTI RAMADANI | C10: 115 | D10: 35 | E10: 35 | F10: 35 | G10: 8 | H10: 14 | I10: 12 | J10: 12 | K10: 13 | L10: 10 | M10: 13 | N10: 10 | O10: 18 | P10: 16 | Q10: 14 | R10: 20 | S10: 12 | T10: 12 | U10: 12 | V10: 7
A11: 3 | B11: AHMAD FAIZ MUIZZUDDIN | C11: 110 | D11: 35 | E11: 35 | F11: 35 | G11: 9 | H11: 12 | I11: 12 | J11: 24 | K11: 14 | L11: 12 | M11: 11 | N11: 11 | O11: 13 | P11: 19 | Q11: 17 | R11: 13 | S11: 8 | T11: 13 | U11: 4 | V11: 10
A12: 4 | B12: AJI SETYA BUDI
A13: 5 | B13: ALAN TAUFIQUROHCMAN
A14: 6 | B14: ALVIN HIDAYAT | C14: 105 | D14: 35 | E14: 35 | F14: 35 | G14: 12 | H14: 9 | I14: 10 | J14: 13 | K14: 19 | L14: 9 | M14: 12 | N14: 14 | O14: 11 | P14: 16 | Q14: 19 | R14: 8 | S14: 14 | T14: 21 | U14: 3 | V14: 13
A15: 7 | B15: BAA'ITS IBRAHIM ALRINAL | C15: 115 | D15: 35 | E15: 80 | F15: 35 | G15: 13 | H15: 15 | I15: 11 | J15: 14 | K15: 9 | L15: 10 | M15: 15 | N15: 22 | O15: 16 | P15: 11 | Q15: 20 | R15: 13 | S15: 10 | T15: 12 | U15: 0 | V15: 11
A16: 8 | B16: DIMAS FAHRI SAIFULLOH | C16: 123 | D16: 35 | E16: 80 | F16: 35 | G16: 9 | H16: 10 | I16: 8 | J16: 10 | K16: 11 | L16: 14 | M16: 11 | N16: 10 | O16: 6 | P16: 15 | Q16: 16 | R16: 22 | S16: 15 | T16: 13 | U16: 13 | V16: 12
A17: 9 | B17: FAIQ SIDQI MUAMAR | C17: 80 | D17: 35 | E17: 65 | F17: 35 | G17: 6 | H17: 18 | I17: 9 | J17: 14 | K17: 17 | L17: 10 | M17: 16 | N17: 14 | O17: 14 | P17: 15 | Q17: 8 | R17: 12 | S17: 16 | T17: 9 | U17: 11 | V17: 15
A18: 10 | B18: FAJAR TRESNO ZULIANTO | C18: 80 | D18: 35 | E18: 35 | F18: 35 | G18: 9 | H18: 12 | I18: 13 | J18: 8 | K18: 8 | L18: 12 | M18: 12 | N18: 16 | O18: 13 | P18: 14 | Q18: 18 | R18: 13 | S18: 12 | T18: 18 | U18: 8 | V18: 14
A19: 11 | B19: IDRIS KHOIRUL KHAFIDZ | C19: 115 | D19: 35 | E19: 80 | F19: 65 | G19: 12 | H19: 11 | I19: 14 | J19: 16 | K19: 12 | L19: 13 | M19: 14 | N19: 7 | O19: 14 | P19: 19 | Q19: 12 | R19: 19 | S19: 8 | T19: 13 | U19: 12 | V19: 9
A20: 12 | B20: KEINZA HUMAM AL BASTOMI | C20: 115 | D20: 35 | E20: 80 | F20: 35 | G20: 11 | H20: 10 | I20: 4 | J20: 8 | K20: 11 | L20: 7 | M20: 12 | N20: 12 | O20: 13 | P20: 18 | Q20: 19 | R20: 22 | S20: 16 | T20: 12 | U20: 18 | V20: 10
A21: 13 | B21: M. FAHRUL FA RIZQI | C21: 80 | D21: 35 | E21: 80 | F21: 35 | G21: 12 | H21: 10 | I21: 13 | J21: 11 | K21: 4 | L21: 11 | M21: 20 | N21: 14 | O21: 11 | P21: 7 | Q21: 19 | R21: 18 | S21: 15 | T21: 19 | U21: 7 | V21: 16
A22: 14 | B22: M. FAIZ NAFIUDDIN
A23: 15 | B23: M. FARIS ZULFA NUR | C23: 105 | D23: 35 | E23: 80 | F23: 35 | G23: 13 | H23: 13 | I23: 13 | J23: 15 | K23: 12 | L23: 10 | M23: 17 | N23: 15 | O23: 9 | P23: 16 | Q23: 14 | R23: 13 | S23: 19 | T23: 17 | U23: 0 | V23: 11
A24: 16 | B24: M. NAUFAL IHYA'ULUMUDDIN
A25: 17 | B25: MAULANA IZZUL HAQQ | C25: 80 | D25: 35 | E25: 80 | F25: 65 | G25: 15 | H25: 13 | I25: 10 | J25: 13 | K25: 11 | L25: 5 | M25: 12 | N25: 17 | O25: 7 | P25: 22 | Q25: 16 | R25: 18 | S25: 18 | T25: 20 | U25: 4 | V25: 9
A26: 18 | B26: MAXI MUSSIYAM ARJU BARAKA | C26: 89 | D26: 35 | E26: 80 | F26: 35 | G26: 9 | H26: 18 | I26: 11 | J26: 14 | K26: 9 | L26: 18 | M26: 12 | N26: 14 | O26: 10 | P26: 13 | Q26: 20 | R26: 15 | S26: 15 | T26: 11 | U26: 5 | V26: 7
A27: 19 | B27: MOH FAIZ AL KHUSNI | C27: 115 | D27: 35 | E27: 35 | F27: 35 | G27: 11 | H27: 12 | I27: 12 | J27: 12 | K27: 12 | L27: 16 | M27: 16 | N27: 10 | O27: 19 | P27: 17 | Q27: 13 | R27: 12 | S27: 11 | T27: 12 | U27: 11 | V27: 13
A28: 20 | B28: MU'AMAR ALVIN HAZIZUL ULUM | C28: 115 | D28: 35 | E28: 80 | F28: 65 | G28: 13 | H28: 18 | I28: 11 | J28: 20 | K28: 12 | L28: 8 | M28: 13 | N28: 14 | O28: 15 | P28: 13 | Q28: 12 | R28: 21 | S28: 11 | T28: 13 | U28: 7 | V28: 7
A29: 21 | B29: MUHAMAD AGUS YUSUF | C29: 85 | D29: 35 | E29: 80 | F29: 35 | G29: 12 | H29: 16 | I29: 10 | J29: 16 | K29: 10 | L29: 7 | M29: 11 | N29: 8 | O29: 15 | P29: 10 | Q29: 17 | R29: 18 | S29: 8 | T29: 15 | U29: 5 | V29: 13
A30: 22 | B30: MUHAMAD WAHYU AFIF MUTHOLIBIN
A31: 23 | B31: MUHAMMAD ARROFI | C31: 80 | D31: 35 | E31: 80 | F31: 35 | G31: 7 | H31: 11 | I31: 13 | J31: 15 | K31: 12 | L31: 6 | M31: 10 | N31: 18 | O31: 23 | P31: 12 | Q31: 13 | R31: 15 | S31: 13 | T31: 21 | U31: 4 | V31: 9
A32: 24 | B32: MUHAMMAD DANIS FIRMAN HIDAYAT | C32: 89 | D32: 35 | E32: 65 | F32: 35 | G32: 9 | H32: 14 | I32: 9 | J32: 13 | K32: 13 | L32: 12 | M32: 20 | N32: 9 | O32: 6 | P32: 13 | Q32: 13 | R32: 14 | S32: 20 | T32: 15 | U32: 20 | V32: 18
A33: 25 | B33: MUHAMMAD FAHRI KHASANUDIN | C33: 110 | D33: 35 | E33: 80 | F33: 65 | G33: 8 | H33: 13 | I33: 10 | J33: 11 | K33: 11 | L33: 7 | M33: 16 | N33: 15 | O33: 23 | P33: 19 | Q33: 20 | R33: 21 | S33: 8 | T33: 22 | U33: 4 | V33: 9
A34: 26 | B34: MUHAMMAD FIRDAUS AL'FATAH | C34: 115 | D34: 35 | E34: 80 | F34: 65 | G34: 7 | H34: 13 | I34: 15 | J34: 13 | K34: 19 | L34: 17 | M34: 16 | N34: 18 | O34: 9 | P34: 10 | Q34: 16 | R34: 14 | S34: 17 | T34: 19 | U34: 2 | V34: 10
A35: 27 | B35: MUHAMMAD HADIDUL AHDA
A36: 28 | B36: MUHAMMAD ILHAM HAQIQI | C36: 80 | D36: 35 | E36: 80 | F36: 35 | G36: 8 | H36: 13 | I36: 12 | J36: 19 | K36: 10 | L36: 16 | M36: 11 | N36: 8 | O36: 15 | P36: 8 | Q36: 17 | R36: 16 | S36: 15 | T36: 13 | U36: 13 | V36: 13
A37: 29 | B37: MUHAMMAD KHIRZA HUDUDIL MAULA | C37: 115 | D37: 35 | E37: 80 | F37: 35 | G37: 10 | H37: 9 | I37: 10 | J37: 12 | K37: 8 | L37: 15 | M37: 17 | N37: 11 | O37: 16 | P37: 9 | Q37: 20 | R37: 26 | S37: 10 | T37: 10 | U37: 5 | V37: 15
A38: 30 | B38: MUHAMMAD RISWAN HANAFI | C38: 109 | D38: 35 | E38: 80 | F38: 35 | G38: 12 | H38: 14 | I38: 12 | J38: 14 | K38: 11 | L38: 8 | M38: 18 | N38: 16 | O38: 12 | P38: 11 | Q38: 19 | R38: 16 | S38: 19 | T38: 19 | U38: 0 | V38: 6
A39: 31 | B39: MUHAMMAD WAHYU WILDANA | C39: 115 | D39: 35 | E39: 80 | F39: 65 | G39: 12 | H39: 13 | I39: 13 | J39: 17 | K39: 11 | L39: 9 | M39: 16 | N39: 13 | O39: 12 | P39: 6 | Q39: 21 | R39: 23 | S39: 17 | T39: 21 | U39: 0 | V39: 10
A40: 32 | B40: RIZQI ALFAN MUBAROK | C40: 110 | D40: 35 | E40: 35 | F40: 35 | G40: 14 | H40: 17 | I40: 13 | J40: 9 | K40: 10 | L40: 12 | M40: 18 | N40: 13 | O40: 12 | P40: 12 | Q40: 20 | R40: 24 | S40: 11 | T40: 17 | U40: 0 | V40: 8
A41: 33 | B41: SYAFA'AT KHOIRUL ANAS | C41: 80 | D41: 35 | E41: 35 | F41: 35 | G41: 10 | H41: 16 | I41: 12 | J41: 13 | K41: 14 | L41: 11 | M41: 15 | N41: 12 | O41: 13 | P41: 16 | Q41: 16 | R41: 10 | S41: 12 | T41: 12 | U41: 12 | V41: 10

Sheet TO 3
A3: REKAPITULASI HASIL ASSESMENT
A4: SMK AL MUSYAFFA' KENDAL
A5: KELAS X TO 3
A7: NO | B7: NAMA LENGKAP | C7: IQ | D7: K35AEPLIN | G7: EPP65
D8: 1 | E8: 2 | F8: 3 | G8: 1 | H8: 2 | I8: 3 | J8: 4 | K8: 5 | L8: 6 | M8: 7 | N8: 8 | O8: 9 | P8: 10 | Q8: 11 | R8: 12 | S8: 13 | T8: 14 | U8: 15 | V8: 16
A9: 1 | B9: ABDULLOH | C9: 115 | D9: 35 | E9: 80 | F9: 65 | G9: 9 | H9: 15 | I9: 10 | J9: 12 | K9: 16 | L9: 9 | M9: 13 | N9: 20 | O9: 13 | P9: 15 | Q9: 11 | R9: 9 | S9: 14 | T9: 15 | U9: 11 | V9: 12
A10: 2 | B10: AKHMAD SOBIRIN | C10: 85 | D10: 35 | E10: 35 | F10: 35 | G10: 7 | H10: 13 | I10: 8 | J10: 17 | K10: 14 | L10: 14 | M10: 15 | N10: 13 | O10: 10 | P10: 12 | Q10: 15 | R10: 16 | S10: 12 | T10: 13 | U10: 11 | V10: 13
A11: 3 | B11: ARRUNA VINO RAVALIAN | C11: 80 | D11: 35 | E11: 35 | F11: 35 | G11: 12 | H11: 15 | I11: 11 | J11: 15 | K11: 12 | L11: 12 | M11: 4 | N11: 12 | O11: 17 | P11: 19 | Q11: 15 | R11: 14 | S11: 8 | T11: 16 | U11: 10 | V11: 15
A12: 4 | B12: BRILLIAN KEVIN NUGROHO | C12: 85 | D12: 35 | E12: 35 | F12: 35 | G12: 9 | H12: 11 | I12: 13 | J12: 10 | K12: 14 | L12: 11 | M12: 13 | N12: 16 | O12: 10 | P12: 16 | Q12: 12 | R12: 13 | S12: 12 | T12: 13 | U12: 19 | V12: 14
A13: 5 | B13: DANU DWI KURNIANSYAH | C13: 80 | D13: 35 | E13: 80 | F13: 35 | G13: 11 | H13: 14 | I13: 9 | J13: 9 | K13: 12 | L13: 12 | M13: 13 | N13: 18 | O13: 12 | P13: 10 | Q13: 20 | R13: 19 | S13: 10 | T13: 16 | U13: 10 | V13: 11
A14: 6 | B14: EKA PRANDI ADINATA | C14: 110 | D14: 35 | E14: 80 | F14: 65 | G14: 12 | H14: 8 | I14: 10 | J14: 8 | K14: 11 | L14: 12 | M14: 18 | N14: 13 | O14: 19 | P14: 9 | Q14: 14 | R14: 16 | S14: 12 | T14: 14 | U14: 18 | V14: 13
A15: 7 | B15: FERDIANSYAH RADITYA ELROSI | C15: 115 | D15: 35 | E15: 80 | F15: 65 | G15: 7 | H15: 12 | I15: 8 | J15: 10 | K15: 11 | L15: 15 | M15: 15 | N15: 12 | O15: 10 | P15: 19 | Q15: 14 | R15: 16 | S15: 12 | T15: 11 | U15: 13 | V15: 17
A16: 8 | B16: HAFIZH RAIHAN | C16: 110 | D16: 35 | E16: 80 | F16: 35 | G16: 13 | H16: 18 | I16: 14 | J16: 17 | K16: 10 | L16: 10 | M16: 18 | N16: 14 | O16: 6 | P16: 11 | Q16: 12 | R16: 16 | S16: 17 | T16: 25 | U16: 0 | V16: 7
A17: 9 | B17: IKFI NIAM ALMUNA | C17: 115 | D17: 35 | E17: 80 | F17: 35 | G17: 12 | H17: 13 | I17: 16 | J17: 13 | K17: 15 | L17: 9 | M17: 13 | N17: 17 | O17: 18 | P17: 11 | Q17: 13 | R17: 19 | S17: 11 | T17: 13 | U17: 2 | V17: 11
A18: 10 | B18: LUVI BAGUS PRASETIO | C18: 115 | D18: 35 | E18: 80 | F18: 35 | G18: 11 | H18: 11 | I18: 13 | J18: 14 | K18: 13 | L18: 6 | M18: 13 | N18: 23 | O18: 8 | P18: 14 | Q18: 17 | R18: 24 | S18: 5 | T18: 14 | U18: 9 | V18: 10
A19: 11 | B19: M. NAZILURRIZQI | C19: 115 | D19: 35 | E19: 80 | F19: 65 | G19: 14 | H19: 19 | I19: 11 | J19: 15 | K19: 11 | L19: 16 | M19: 7 | N19: 14 | O19: 3 | P19: 22 | Q19: 12 | R19: 8 | S19: 17 | T19: 19 | U19: 8 | V19: 15
A20: 12 | B20: MANAHILUL URFAN | C20: 115 | D20: 35 | E20: 80 | F20: 65 | G20: 6 | H20: 11 | I20: 15 | J20: 13 | K20: 12 | L20: 17 | M20: 9 | N20: 16 | O20: 13 | P20: 8 | Q20: 16 | R20: 12 | S20: 13 | T20: 11 | U20: 13 | V20: 16
... A34: 26 | B34: RAJWA DHIYA'UL HAQ | C34: 115 | D34: 35 | E34: 80 | F34: 35 | G34: 12 | H34: 14 | I34: 9 | J34: 5 | K34: 9 | L34: 15 | M34: 19 | N34: 15 | O34: 9 | P34: 16 | Q34: 13 | R34: 13 | S34: 15 | T34: 12 | U34: 11 | V34: 17

Sheet TO 4
A3: REKAPITULASI HASIL ASSESMENT
A4: SMK AL MUSYAFFA' KENDAL
A5: KELAS X TO 4
A7: NO | B7: NAMA LENGKAP | C7: IQ | D7: K35AEPLIN | G7: EPP65
D8: 1 | E8: 2 | F8: 3 | G8: 1 | H8: 2 | I8: 3 | J8: 4 | K8: 5 | L8: 6 | M8: 7 | N8: 8 | O8: 9 | P8: 10 | Q8: 11 | R8: 12 | S8: 13 | T8: 14 | U8: 15 | V8: 16
A9: 1 | B9: ADITYA EKA NUR AKBAR | C9: 80 | D9: 35 | E9: 35 | F9: 35 | G9: 10 | H9: 14 | I9: 11 | J9: 15 | K9: 13 | L9: 12 | M9: 10 | N9: 17 | O9: 9 | P9: 13 | Q9: 10 | R9: 11 | S9: 12 | T9: 12 | U9: 18 | V9: 18
A10: 2 | B10: ARI WIBOWO | C10: 80 | D10: 35 | E10: 80 | F10: 35 | G10: 9 | H10: 10 | I10: 13 | J10: 12 | K10: 15 | L10: 12 | M10: 14 | N10: 18 | O10: 14 | P10: 16 | Q10: 13 | R10: 11 | S10: 15 | T10: 8 | U10: 11 | V10: 15
A11: 3 | B11: AZMI ULI SYIFA
A12: 4 | B12: BRIYAN ANTONIO FIRIN | C12: 115 | D12: 35 | E12: 35 | F12: 35 | G12: 11 | H12: 12 | I12: 13 | J12: 12 | K12: 10 | L12: 10 | M12: 13 | N12: 17 | O12: 15 | P12: 16 | Q12: 18 | R12: 6 | S12: 16 | T12: 13 | U12: 6 | V12: 18
A13: 5 | B13: DESTIAN ARRASYID | C13: 109 | D13: 35 | E13: 35 | F13: 35 | G13: 12 | H13: 13 | I13: 9 | J13: 16 | K13: 13 | L13: 4 | M13: 18 | N13: 9 | O13: 12 | P13: 8 | Q13: 15 | R13: 16 | S13: 15 | T13: 24 | U13: 7 | V13: 14
A14: 6 | B14: FAHMI KAUTSAR | C14: 89 | D14: 35 | E14: 35 | F14: 35 | G14: 13 | H14: 11 | I14: 10 | J14: 17 | K14: 11 | L14: 5 | M14: 18 | N14: 17 | O14: 15 | P14: 17 | Q14: 14 | R14: 20 | S14: 16 | T14: 12 | U14: 1 | V14: 11
A15: 7 | B15: HARUN MAULANA | C15: 109 | D15: 35 | E15: 80 | F15: 65 | G15: 11 | H15: 16 | I15: 14 | J15: 4 | K15: 11 | L15: 10 | M15: 12 | N15: 21 | O15: 9 | P15: 15 | Q15: 16 | R15: 19 | S15: 9 | T15: 11 | U15: 10 | V15: 17
A16: 8 | B16: LINTANG WAHYU SAPUTRA | C16: 80 | D16: 35 | E16: 80 | F16: 35 | G16: 6 | H16: 13 | I16: 12 | J16: 11 | K16: 6 | L16: 15 | M16: 15 | N16: 13 | O16: 10 | P16: 13 | Q16: 21 | R16: 9 | S16: 16 | T16: 13 | U16: 12 | V16: 17
A17: 9 | B17: M AFFAN ANDHIKA RAMA DHANI | C17: 109 | D17: 35 | E17: 80 | F17: 35 | G17: 8 | H17: 11 | I17: 10 | J17: 12 | K17: 13 | L17: 12 | M17: 12 | N17: 14 | O17: 15 | P17: 13 | Q17: 16 | R17: 13 | S17: 14 | T17: 14 | U17: 15 | V17: 8
A18: 10 | B18: M. IBROHIM AKBAR | C18: 115 | D18: 35 | E18: 80 | F18: 35 | G18: 11 | H18: 12 | I18: 12 | J18: 6 | K18: 13 | L18: 6 | M18: 16 | N18: 15 | O18: 20 | P18: 15 | Q18: 20 | R18: 11 | S18: 12 | T18: 11 | U18: 8 | V18: 17
A19: 11 | B19: MUAKHIRU YUSUF ASHARI | C19: 115 | D19: 35 | E19: 80 | F19: 65 | G19: 12 | H19: 14 | I19: 14 | J19: 11 | K19: 16 | L19: 8 | M19: 19 | N19: 12 | O19: 6 | P19: 10 | Q19: 18 | R19: 13 | S19: 21 | T19: 15 | U19: 7 | V19: 9
A20: 12 | B20: MUHAMAD FAHIM DAROINI | C20: 115 | D20: 35 | E20: 80 | F20: 35 | G20: 12 | H20: 15 | I20: 8 | J20: 14 | K20: 10 | L20: 10 | M20: 11 | N20: 14 | O20: 16 | P20: 15 | Q20: 18 | R20: 13 | S20: 8 | T20: 17 | U20: 13 | V20: 12
A21: 13 | B21: MUHAMAD ZAQI | C21: 85 | D21: 35 | E21: 80 | F21: 35 | G21: 9 | H21: 9 | I21: 10 | J21: 10 | K21: 15 | L21: 13 | M21: 9 | N21: 13 | O21: 13 | P21: 15 | Q21: 16 | R21: 15 | S21: 11 | T21: 11 | U21: 13 | V21: 16
A22: 14 | B22: MUHAMMAD ARBAH IZZA TULHAQ | C22: 90 | D22: 35 | E22: 80 | F22: 35 | G22: 8 | H22: 13 | I22: 8 | J22: 13 | K22: 12 | L22: 13 | M22: 12 | N22: 13 | O22: 12 | P22: 17 | Q22: 12 | R22: 14 | S22: 11 | T22: 15 | U22: 10 | V22: 17
A23: 15 | B23: MUHAMMAD FAIRUS IRSYADUZZAIDAN
A24: 16 | B24: MUHAMMAD FATKHUR ROZAQ | C24: 115 | D24: 35 | E24: 80 | F24: 35 | G24: 13 | H24: 15 | I24: 9 | J24: 11 | K24: 10 | L24: 10 | M24: 17 | N24: 12 | O24: 15 | P24: 7 | Q24: 21 | R24: 15 | S24: 15 | T24: 12 | U24: 11 | V24: 15
A25: 17 | B25: MUHAMMAD HAFIZH ATHA | C25: 115 | D25: 65 | E25: 80 | F25: 65 | G25: 12 | H25: 10 | I25: 9 | J25: 13 | K25: 9 | L25: 10 | M25: 14 | N25: 17 | O25: 16 | P25: 13 | Q25: 15 | R25: 11 | S25: 17 | T25: 14 | U25: 11 | V25: 13
A26: 18 | B26: MUHAMMAD IBNU SHOLEH | C26: 115 | D26: 35 | E26: 35 | F26: 35 | G26: 8 | H26: 15 | I26: 13 | J26: 19 | K26: 7 | L26: 4 | M26: 12 | N26: 17 | O26: 15 | P26: 12 | Q26: 11 | R26: 22 | S26: 15 | T26: 20 | U26: 3 | V26: 7
A27: 19 | B27: MUHAMMAD IZZA FASYA | C27: 115 | D27: 65 | E27: 80 | F27: 65 | G27: 7 | H27: 12 | I27: 9 | J27: 11 | K27: 11 | L27: 6 | M27: 17 | N27: 18 | O27: 23 | P27: 9 | Q27: 16 | R27: 21 | S27: 7 | T27: 16 | U27: 5 | V27: 14
A28: 20 | B28: MUHAMMAD LABIB FAZA | C28: 109 | D28: 35 | E28: 80 | F28: 65 | G28: 12 | H28: 12 | I28: 8 | J28: 14 | K28: 6 | L28: 9 | M28: 12 | N28: 16 | O28: 10 | P28: 12 | Q28: 18 | R28: 14 | S28: 24 | T28: 18 | U28: 5 | V28: 17
A29: 21 | B29: MUHAMMAD REVA AKBAR ANIFUDIN
A30: 22 | B30: MUHAMMAD WILDAN ALFIYANNUR | C30: 105 | D30: 35 | E30: 80 | F30: 35 | G30: 9 | H30: 11 | I30: 15 | J30: 16 | K30: 14 | L30: 13 | M30: 12 | N30: 13 | O30: 18 | P30: 15 | Q30: 12 | R30: 14 | S30: 19 | T30: 13 | U30: 11 | V30: 15
A31: 23 | B31: NAUVAL MAULANA | C31: 85 | D31: 35 | E31: 80 | F31: 35 | G31: 14 | H31: 14 | I31: 15 | J31: 16 | K31: 10 | L31: 12 | M31: 12 | N31: 13 | O31: 10 | P31: 17 | Q31: 21 | R31: 18 | S31: 11 | T31: 23 | U31: 2 | V31: 16
A32: 24 | B32: NOVAL ERLANDA FRAMUDIA | C32: 85 | D32: 35 | E32: 80 | F32: 35 | G32: 12 | H32: 18 | I32: 10 | J32: 13 | K32: 10 | L32: 7 | M32: 18 | N32: 16 | O32: 19 | P32: 17 | Q32: 23 | R32: 21 | S32: 17 | T32: 18 | U32: 0 | V32: 4
A33: 25 | B33: OASE MUHAMMAD RIZKY
A34: 26 | B34: RAFIF ABIYYU RAHMAN | C34: 90 | D34: 35 | E34: 80 | F34: 65 | G34: 12 | H34: 14 | I34: 9 | J34: 13 | K34: 7 | L34: 7 | M34: 21 | N34: 22 | O34: 16 | P34: 15 | Q34: 15 | R34: 19 | S34: 13 | T34: 14 | U34: 2 | V34: 8
A35: 27 | B35: RIZEQ ZANUAR RIFQI | C35: 110 | D35: 35 | E35: 80 | F35: 35 | G35: 12 | H35: 13 | I35: 11 | J35: 11 | K35: 11 | L35: 9 | M35: 16 | N35: 13 | O35: 18 | P35: 11 | Q35: 20 | R35: 23 | S35: 13 | T35: 16 | U35: 4 | V35: 5
A36: 28 | B36: SYAFA'AT ABDUL GHOFUR | C36: 115 | D36: 35 | E36: 80 | F36: 35 | G36: 15 | H36: 9 | I36: 7 | J36: 9 | K36: 11 | L36: 12 | M36: 10 | N36: 19 | O36: 10 | P36: 17 | Q36: 20 | R36: 15 | S36: 13 | T36: 11 | U36: 9 | V36: 23
A37: 29 | B37: ZAIDAN KHAFIDZ KHAMANI | C37: 110 | D37: 35 | E37: 80 | F37: 35 | G37: 11 | H37: 11 | I37: 9 | J37: 10 | K37: 8 | L37: 9 | M37: 17 | N37: 17 | O37: 23 | P37: 10 | Q37: 16 | R37: 13 | S37: 12 | T37: 17 | U37: 12 | V37: 11

Sheet TO 5
A3: REKAPITULASI HASIL ASSESMENT
A4: SMK AL MUSYAFFA' KENDAL
A5: KELAS X TO 5
A7: NO | B7: NAMA LENGKAP | C7: IQ | D7: K35AEPLIN | G7: EPP65
D8: 1 | E8: 2 | F8: 3 | G8: 1 | H8: 2 | I8: 3 | J8: 4 | K8: 5 | L8: 6 | M8: 7 | N8: 8 | O8: 9 | P8: 10 | Q8: 11 | R8: 12 | S8: 13 | T8: 14 | U8: 15 | V8: 16
A9: 1 | B9: AFZAN BUNAYA | C9: 109 | D9: 35 | E9: 35 | F9: 35 | G9: 11 | H9: 13 | I9: 12 | J9: 13 | K9: 15 | L9: 7 | M9: 12 | N9: 16 | O9: 19 | P9: 15 | Q9: 17 | R9: 23 | S9: 14 | T9: 16 | U9: 6 | V9: 13
A10: 2 | B10: AHMAD JAZURI | C10: 119 | D10: 35 | E10: 80 | F10: 35 | G10: 9 | H10: 17 | I10: 11 | J10: 15 | K10: 8 | L10: 11 | M10: 12 | N10: 8 | O10: 6 | P10: 20 | Q10: 12 | R10: 23 | S10: 17 | T10: 23 | U10: 10 | V10: 13
A11: 3 | B11: ARIF SYAH PUTRADEWA | C11: 80 | D11: 35 | E11: 80 | F11: 35 | G11: 10 | H11: 21 | I11: 17 | J11: 12 | K11: 9 | L11: 12 | M11: 16 | N11: 14 | O11: 9 | P11: 18 | Q11: 13 | R11: 13 | S11: 12 | T11: 23 | U11: 7 | V11: 15
A12: 4 | B12: DAFFA ARDIAN MAULANA | C12: 119 | D12: 35 | E12: 80 | F12: 65 | G12: 12 | H12: 11 | I12: 9 | J12: 14 | K12: 13 | L12: 8 | M12: 19 | N12: 10 | O12: 24 | P12: 13 | Q12: 22 | R12: 15 | S12: 16 | T12: 14 | U12: 12 | V12: 14
A13: 5 | B13: DIMAS MAULANA | C13: 109 | D13: 35 | E13: 80 | F13: 65 | G13: 13 | H13: 16 | I13: 11 | J13: 22 | K13: 13 | L13: 9 | M13: 13 | N13: 21 | O13: 17 | P13: 9 | Q13: 19 | R13: 18 | S13: 13 | T13: 15 | U13: 3 | V13: 10
A14: 6 | B14: FARHAN ADITYA RIVALDO | C14: 80 | D14: 35 | E14: 35 | F14: 35 | G14: 5 | H14: 12 | I14: 17 | J14: 21 | K14: 20 | L14: 18 | M14: 14 | N14: 14 | O14: 18 | P14: 11 | Q14: 13 | R14: 7 | S14: 7 | T14: 14 | U14: 10 | V14: 14
A15: 7 | B15: GALANG FATIH ALFARIZA | C15: 90 | D15: 35 | E15: 80 | F15: 65 | G15: 8 | H15: 14 | I15: 10 | J15: 7 | K15: 15 | L15: 11 | M15: 17 | N15: 10 | O15: 15 | P15: 16 | Q15: 17 | R15: 14 | S15: 13 | T15: 12 | U15: 16 | V15: 22
A16: 8 | B16: HADI LUTFI SAPUTRA | C16: 80 | D16: 35 | E16: 80 | F16: 35 | G16: 2 | H16: 19 | I16: 11 | J16: 16 | K16: 12 | L16: 17 | M16: 12 | N16: 16 | O16: 12 | P16: 11 | Q16: 16 | R16: 11 | S16: 16 | T16: 11 | U16: 16 | V16: 11
A17: 9 | B17: IGUH PRAYOGA | C17: 115 | D17: 35 | E17: 80 | F17: 35 | G17: 10 | H17: 10 | I17: 11 | J17: 12 | K17: 12 | L17: 15 | M17: 19 | N17: 16 | O17: 6 | P17: 16 | Q17: 19 | R17: 16 | S17: 13 | T17: 16 | U17: 16 | V17: 14
A18: 10 | B18: IRFAN KOSWANTORO NUR HAVID | C18: 115 | D18: 35 | E18: 65 | F18: 35 | G18: 15 | H18: 18 | I18: 7 | J18: 18 | K18: 15 | L18: 15 | M18: 5 | N18: 17 | O18: 9 | P18: 13 | Q18: 23 | R18: 19 | S18: 12 | T18: 18 | U18: 1 | V18: 22
A19: 11 | B19: IZZA MUTAWAKIL DHAROTUN | C19: 105 | D19: 35 | E19: 80 | F19: 35 | G19: 11 | H19: 13 | I19: 10 | J19: 16 | K19: 9 | L19: 12 | M19: 18 | N19: 17 | O19: 13 | P19: 13 | Q19: 18 | R19: 21 | S19: 8 | T19: 12 | U19: 16 | V19: 14
A20: 12 | B20: LUSTER ANIPAR | C20: 80 | D20: 35 | E20: 35 | F20: 35 | G20: 9 | H20: 14 | I20: 12 | J20: 12 | K20: 17 | L20: 16 | M20: 18 | N20: 13 | O20: 7 | P20: 18 | Q20: 15 | R20: 15 | S20: 15 | T20: 12 | U20: 12 | V20: 14
... A37: 29 | B37: YAHYA ZAFARONI | C37: 80 | D37: 35 | E37: 35 | F37: 35 | G37: 7 | H37: 12 | I37: 12 | J37: 16 | K37: 14 | L37: 16 | M37: 18 | N37: 12 | O37: 15 | P37: 12 | Q37: 16 | R37: 11 | S37: 11 | T37: 12 | U37: 16 | V37: 15

Sheet KU 1
A3: REKAPITULASI HASIL ASSESMENT
A4: SMK AL MUSYAFFA' KENDAL
A5: KELAS X KU 1
A7: NO | B7: NAMA LENGKAP | C7: IQ | D7: K35AEPLIN | G7: EPP65
D8: 1 | E8: 2 | F8: 3 | G8: 1 | H8: 2 | I8: 3 | J8: 4 | K8: 5 | L8: 6 | M8: 7 | N8: 8 | O8: 9 | P8: 10 | Q8: 11 | R8: 12 | S8: 13 | T8: 14 | U8: 15 | V8: 16
A9: 1 | B9: AJENG SETIA NINGSIH | C9: 115 | D9: 35 | E9: 80 | F9: 35 | G9: 12 | H9: 16 | I9: 14 | J9: 13 | K9: 15 | L9: 8 | M9: 12 | N9: 15 | O9: 12 | P9: 11 | Q9: 17 | R9: 15 | S9: 19 | T9: 12 | U9: 5 | V9: 9
A10: 2 | B10: ANNISA MAULIDA RAHMA | C10: 119 | D10: 65 | E10: 80 | F10: 65 | G10: 10 | H10: 14 | I10: 8 | J10: 9 | K10: 10 | L10: 7 | M10: 17 | N10: 18 | O10: 13 | P10: 8 | Q10: 19 | R10: 22 | S10: 21 | T10: 18 | U10: 3 | V10: 10
A11: 3 | B11: ASHFANA FIZA AQILA | C11: 110 | D11: 35 | E11: 80 | F11: 35 | G11: 10 | H11: 14 | I11: 16 | J11: 11 | K11: 10 | L11: 9 | M11: 22 | N11: 21 | O11: 16 | P11: 6 | Q11: 18 | R11: 16 | S11: 12 | T11: 17 | U11: 1 | V11: 6
A12: 4 | B12: AYUDYA MAILASYUFA | C12: 105 | D12: 35 | E12: 80 | F12: 35 | G12: 11 | H12: 12 | I12: 11 | J12: 14 | K12: 12 | L12: 10 | M12: 19 | N12: 13 | O12: 14 | P12: 10 | Q12: 19 | R12: 16 | S12: 15 | T12: 11 | U12: 0 | V12: 18
A13: 5 | B13: CAHAYA APRILIA PUTRI | C13: 85 | D13: 35 | E13: 35 | F13: 35 | G13: 12 | H13: 14 | I13: 9 | J13: 13 | K13: 7 | L13: 7 | M13: 21 | N13: 22 | O13: 16 | P13: 15 | Q13: 15 | R13: 19 | S13: 13 | T13: 14 | U13: 2 | V13: 8
A14: 6 | B14: CHASNA KANIYAH | C14: 89 | D14: 35 | E14: 80 | F14: 35 | G14: 12 | H14: 13 | I14: 11 | J14: 11 | K14: 11 | L14: 9 | M14: 16 | N14: 13 | O14: 18 | P14: 11 | Q14: 20 | R14: 23 | S14: 13 | T14: 16 | U14: 4 | V14: 5
A15: 7 | B15: DINA MAULIDA | C15: 105 | D15: 35 | E15: 80 | F15: 35 | G15: 15 | H15: 9 | I15: 7 | J15: 9 | K15: 11 | L15: 12 | M15: 10 | N15: 19 | O15: 10 | P15: 17 | Q15: 20 | R15: 15 | S15: 13 | T15: 11 | U15: 9 | V15: 23
A16: 8 | B16: FAIQOTUZ ZAHRO | C16: 80 | D16: 35 | E16: 35 | F16: 35 | G16: 11 | H16: 11 | I16: 9 | J16: 10 | K16: 8 | L16: 9 | M16: 17 | N16: 17 | O16: 23 | P16: 10 | Q16: 16 | R16: 13 | S16: 12 | T16: 17 | U16: 12 | V16: 11
A17: 9 | B17: FIDA AZIZAH | C17: 85 | D17: 35 | E17: 80 | F17: 35 | G17: 9 | H17: 15 | I17: 12 | J17: 14 | K17: 10 | L17: 6 | M17: 14 | N17: 15 | O17: 11 | P17: 7 | Q17: 21 | R17: 15 | S17: 17 | T17: 19 | U17: 5 | V17: 14
A18: 10 | B18: FIRDA YULIYA ISTIANTI | C18: 115 | D18: 65 | E18: 80 | F18: 65 | G18: 11 | H18: 11 | I18: 12 | J18: 7 | K18: 7 | L18: 14 | M18: 17 | N18: 16 | O18: 22 | P18: 15 | Q18: 17 | R18: 9 | S18: 12 | T18: 13 | U18: 8 | V18: 15
A19: 11 | B19: HULWA SYAKILA NAJMASALISA | C19: 115 | D19: 35 | E19: 80 | F19: 35 | G19: 12 | H19: 15 | I19: 13 | J19: 13 | K19: 9 | L19: 11 | M19: 9 | N19: 17 | O19: 10 | P19: 12 | Q19: 16 | R19: 15 | S19: 13 | T19: 23 | U19: 0 | V19: 8
A20: 12 | B20: INTAN RAHMA FEBRIANI | C20: 119 | D20: 35 | E20: 80 | F20: 35 | G20: 13 | H20: 9 | I20: 11 | J20: 15 | K20: 13 | L20: 13 | M20: 20 | N20: 18 | O20: 10 | P20: 8 | Q20: 21 | R20: 7 | S20: 22 | T20: 11 | U20: 3 | V20: 14
... A32: 24 | B32: VIKA NUR KUMAIDAH | C32: 80 | D32: 35 | E32: 80 | F32: 35 | G32: 12 | H32: 13 | I32: 8 | J32: 9 | K32: 8 | L32: 10 | M32: 20 | N32: 17 | O32: 19 | P32: 13 | Q32: 19 | R32: 15 | S32: 10 | T32: 14 | U32: 13 | V32: 11

Sheet KU 2
A3: REKAPITULASI HASIL ASSESMENT
A4: SMK AL MUSYAFFA' KENDAL
A5: KELAS X KU 2
A7: NO | B7: NAMA LENGKAP | C7: IQ | D7: K35AEPLIN | G7: EPP65
D8: 1 | E8: 2 | F8: 3 | G8: 1 | H8: 2 | I8: 3 | J8: 4 | K8: 5 | L8: 6 | M8: 7 | N8: 8 | O8: 9 | P8: 10 | Q8: 11 | R8: 12 | S8: 13 | T8: 14 | U8: 15 | V8: 16
A9: 1 | B9: ANDINI MARISA KAYSI QULUB | C9: 89 | D9: 35 | E9: 65 | F9: 35 | G9: 13 | H9: 15 | I9: 9 | J9: 11 | K9: 10 | L9: 10 | M9: 17 | N9: 12 | O9: 15 | P9: 7 | Q9: 21 | R9: 15 | S9: 15 | T9: 12 | U9: 11 | V9: 15
A10: 2 | B10: AQILA RUSYDA AZZUHROH | C10: 115 | D10: 35 | E10: 80 | F10: 35 | G10: 12 | H10: 10 | I10: 9 | J10: 13 | K10: 9 | L10: 10 | M10: 14 | N10: 17 | O10: 16 | P10: 13 | Q10: 15 | R10: 11 | S10: 17 | T10: 14 | U10: 11 | V10: 13
A11: 3 | B11: AULIA LARASATI | C11: 89 | D11: 35 | E11: 80 | F11: 35 | G11: 8 | H11: 15 | I11: 13 | J11: 19 | K11: 7 | L11: 4 | M11: 12 | N11: 17 | O11: 15 | P11: 12 | Q11: 11 | R11: 22 | S11: 15 | T11: 20 | U11: 3 | V11: 7
A12: 4 | B12: AYYAS AUFA ZAHRAN | C12: 115 | D12: 35 | E12: 80 | F12: 35 | G12: 7 | H12: 12 | I12: 9 | J12: 11 | K12: 11 | L12: 6 | M12: 17 | N12: 18 | O12: 23 | P12: 9 | Q12: 16 | R12: 21 | S12: 7 | T12: 16 | U12: 5 | V12: 14
A13: 5 | B13: CAHYANI SALSABILLA PUTRI | C13: 89 | D13: 35 | E13: 80 | F13: 35 | G13: 12 | H13: 12 | I13: 8 | J13: 14 | K13: 6 | L13: 9 | M13: 12 | N13: 16 | O13: 10 | P13: 12 | Q13: 18 | R13: 14 | S13: 24 | T13: 18 | U13: 5 | V13: 17
A14: 6 | B14: DEWI LINTANG RATU NINGRUM | C14: 115 | D14: 35 | E14: 80 | F14: 65 | G14: 11 | H14: 8 | I14: 11 | J14: 7 | K14: 11 | L14: 18 | M14: 15 | N14: 14 | O14: 12 | P14: 13 | Q14: 21 | R14: 17 | S14: 9 | T14: 9 | U14: 17 | V14: 15
A15: 7 | B15: DINA KHAMIDAH | C15: 90 | D15: 35 | E15: 35 | F15: 35 | G15: 10 | H15: 19 | I15: 14 | J15: 9 | K15: 7 | L15: 9 | M15: 14 | N15: 15 | O15: 8 | P15: 11 | Q15: 19 | R15: 15 | S15: 14 | T15: 23 | U15: 0 | V15: 18
A16: 8 | B16: DWI ANISAUR ROHMAH | C16: 80 | D16: 35 | E16: 80 | F16: 35 | G16: 6 | H16: 11 | I16: 11 | J16: 11 | K16: 12 | L16: 7 | M16: 15 | N16: 15 | O16: 12 | P16: 12 | Q16: 23 | R16: 10 | S16: 18 | T16: 10 | U16: 14 | V16: 19
A17: 9 | B17: FINA DZATIN NI'MAH | C17: 80 | D17: 35 | E17: 80 | F17: 35 | G17: 13 | H17: 15 | I17: 8 | J17: 15 | K17: 15 | L17: 5 | M17: 14 | N17: 15 | O17: 15 | P17: 16 | Q17: 14 | R17: 17 | S17: 12 | T17: 16 | U17: 6 | V17: 11
A18: 10 | B18: HEPI ZAHRA RIFA PUTRI | C18: 115 | D18: 35 | E18: 80 | F18: 65 | G18: 13 | H18: 15 | I18: 11 | J18: 12 | K18: 12 | L18: 7 | M18: 13 | N18: 11 | O18: 7 | P18: 15 | Q18: 25 | R18: 23 | S18: 14 | T18: 21 | U18: 0 | V18: 9
A19: 11 | B19: HUSNA RORINSIA | C19: 115 | D19: 35 | E19: 80 | F19: 35 | G19: 11 | H19: 15 | I19: 10 | J19: 15 | K19: 10 | L19: 11 | M19: 10 | N19: 14 | O19: 19 | P19: 17 | Q19: 15 | R19: 16 | S19: 15 | T19: 13 | U19: 2 | V19: 14
A20: 12 | B20: IVANA SAFITRI | C20: 109 | D20: 35 | E20: 35 | F20: 35 | G20: 11 | H20: 11 | I20: 7 | J20: 12 | K20: 10 | L20: 13 | M20: 18 | N20: 18 | O20: 12 | P20: 11 | Q20: 18 | R20: 15 | S20: 15 | T20: 15 | U20: 8 | V20: 12
... A33: 25 | B33: YADI RAHMA NAYSELA | C33: 90 | D33: 35 | E33: 80 | F33: 35 | G33: 11 | H33: 16 | I33: 11 | J33: 11 | K33: 10 | L33: 11 | M33: 12 | N33: 16 | O33: 9 | P33: 11 | Q33: 20 | R33: 21 | S33: 29 | T33: 20 | U33: 0 | V33: 8

Sheet BU 1
A3: REKAPITULASI HASIL ASSESMENT
A4: SMK AL MUSYAFFA' KENDAL
A5: KELAS X BU 1
A7: NO | B7: NAMA LENGKAP | C7: IQ | D7: K35AEPLIN | G7: EPP65
D8: 1 | E8: 2 | F8: 3 | G8: 1 | H8: 2 | I8: 3 | J8: 4 | K8: 5 | L8: 6 | M8: 7 | N8: 8 | O8: 9 | P8: 10 | Q8: 11 | R8: 12 | S8: 13 | T8: 14 | U8: 15 | V8: 16
A9: 1 | B9: AGHNI MUFIDA | C9: 115 | D9: 35 | E9: 80 | F9: 65 | G9: 11 | H9: 14 | I9: 19 | J9: 12 | K9: 12 | L9: 8 | M9: 9 | N9: 10 | O9: 7 | P9: 5 | Q9: 21 | R9: 9 | S9: 16 | T9: 18 | U9: 13 | V9: 9
A10: 2 | B10: ALFI AMELIA NABILLA | C10: 109 | D10: 35 | E10: 80 | F10: 35 | G10: 11 | H10: 19 | I10: 10 | J10: 10 | K10: 12 | L10: 11 | M10: 11 | N10: 17 | O10: 10 | P10: 17 | Q10: 14 | R10: 12 | S10: 20 | T10: 11 | U10: 2 | V10: 16
A11: 3 | B11: ALIFIA EKA KHOIRUNISA | C11: 80 | D11: 35 | E11: 80 | F11: 35 | G11: 10 | H11: 13 | I11: 9 | J11: 11 | K11: 8 | L11: 13 | M11: 13 | N11: 13 | O11: 15 | P11: 7 | Q11: 21 | R11: 23 | S11: 11 | T11: 18 | U11: 3 | V11: 12
A12: 4 | B12: AMALIA SAFITRI | C12: 80 | D12: 35 | E12: 35 | F12: 35 | G12: 8 | H12: 10 | I12: 19 | J12: 11 | K12: 12 | L12: 13 | M12: 12 | N12: 16 | O12: 10 | P12: 14 | Q12: 13 | R12: 15 | S12: 11 | T12: 14 | U12: 10 | V12: 11
A13: 5 | B13: ANIQ JIHAN FURAIDA | C13: 115 | D13: 35 | E13: 80 | F13: 35 | G13: 11 | H13: 14 | I13: 17 | J13: 10 | K13: 11 | L13: 2 | M13: 13 | N13: 15 | O13: 15 | P13: 9 | Q13: 21 | R13: 13 | S13: 21 | T13: 24 | U13: 3 | V13: 7
A14: 6 | B14: APRILIANA NABILA ZAHRA
A15: 7 | B15: ARINA DARSI ILMIA | C15: 80 | D15: 35 | E15: 35 | F15: 35 | G15: 12 | H15: 16 | I15: 14 | J15: 10 | K15: 13 | L15: 10 | M15: 14 | N15: 18 | O15: 7 | P15: 18 | Q15: 22 | R15: 16 | S15: 21 | T15: 12 | U15: 5 | V15: 5
A16: 8 | B16: ATIA NI'MATURROHMAH | C16: 115 | D16: 35 | E16: 80 | F16: 35 | G16: 11 | H16: 16 | I16: 10 | J16: 13 | K16: 8 | L16: 15 | M16: 8 | N16: 15 | O16: 7 | P16: 16 | Q16: 14 | R16: 4 | S16: 17 | T16: 17 | U16: 10 | V16: 23
A17: 9 | B17: AURA SAKINA NURTAUFIK | C17: 109 | D17: 35 | E17: 80 | F17: 65 | G17: 15 | H17: 13 | I17: 9 | J17: 14 | K17: 7 | L17: 8 | M17: 17 | N17: 22 | O17: 16 | P17: 17 | Q17: 20 | R17: 21 | S17: 9 | T17: 16 | U17: 0 | V17: 5
A18: 10 | B18: DEVI FUJIAWATI | C18: 89 | D18: 35 | E18: 80 | F18: 65 | G18: 12 | H18: 18 | I18: 11 | J18: 13 | K18: 9 | L18: 7 | M18: 14 | N18: 13 | O18: 20 | P18: 10 | Q18: 16 | R18: 20 | S18: 14 | T18: 13 | U18: 8 | V18: 9
A19: 11 | B19: DIANA IKA KURNIAWATI | C19: 115 | D19: 35 | E19: 80 | F19: 65 | G19: 10 | H19: 12 | I19: 9 | J19: 12 | K19: 4 | L19: 15 | M19: 19 | N19: 17 | O19: 6 | P19: 9 | Q19: 18 | R19: 16 | S19: 20 | T19: 17 | U19: 8 | V19: 12
A20: 12 | B20: DINDA REFINA PUTRI
A21: 13 | B21: DONA NURUL ALIYAH | C21: 115 | D21: 35 | E21: 35 | F21: 35 | G21: 13 | H21: 16 | I21: 13 | J21: 15 | K21: 7 | L21: 13 | M21: 5 | N21: 17 | O21: 18 | P21: 11 | Q21: 20 | R21: 16 | S21: 19 | T21: 17 | U21: 0 | V21: 8
A22: 14 | B22: ENNESIA RENATA NUGRAHA | C22: 115 | D22: 35 | E22: 80 | F22: 35 | G22: 14 | H22: 17 | I22: 11 | J22: 10 | K22: 14 | L22: 11 | M22: 12 | N22: 10 | O22: 25 | P22: 10 | Q22: 18 | R22: 17 | S22: 13 | T22: 15 | U22: 1 | V22: 9
A23: 15 | B23: IMAS SETYANINGTYAS | C23: 80 | D23: 35 | E23: 80 | F23: 35 | G23: 10 | H23: 7 | I23: 11 | J23: 10 | K23: 12 | L23: 8 | M23: 11 | N23: 18 | O23: 9 | P23: 16 | Q23: 24 | R23: 22 | S23: 9 | T23: 13 | U23: 11 | V23: 13
A24: 16 | B24: KAYLA SYIFA RAMADHANI | C24: 89 | D24: 35 | E24: 80 | F24: 65 | G24: 11 | H24: 13 | I24: 15 | J24: 14 | K24: 13 | L24: 10 | M24: 15 | N24: 17 | O24: 15 | P24: 10 | Q24: 15 | R24: 17 | S24: 14 | T24: 18 | U24: 6 | V24: 3
A25: 17 | B25: KHOIRUN NISA AZ ZAHRA | C25: 85 | D25: 35 | E25: 80 | F25: 35 | G25: 11 | H25: 8 | I25: 11 | J25: 23 | K25: 10 | L25: 14 | M25: 14 | N25: 17 | O25: 9 | P25: 15 | Q25: 19 | R25: 14 | S25: 22 | T25: 14 | U25: 4 | V25: 13
A26: 18 | B26: LU'LU'UN NAZILATUN NI'MAH | C26: 109 | D26: 35 | E26: 80 | F26: 35 | G26: 13 | H26: 15 | I26: 10 | J26: 18 | K26: 9 | L26: 7 | M26: 20 | N26: 15 | O26: 11 | P26: 11 | Q26: 13 | R26: 18 | S26: 13 | T26: 21 | U26: 3 | V26: 2
A27: 19 | B27: MILA HIKMATUL HIDAYAH | C27: 90 | D27: 35 | E27: 35 | F27: 35 | G27: 10 | H27: 13 | I27: 10 | J27: 11 | K27: 10 | L27: 13 | M27: 15 | N27: 11 | O27: 16 | P27: 9 | Q27: 22 | R27: 7 | S27: 12 | T27: 17 | U27: 11 | V27: 16
A28: 20 | B28: NABILA HABIBATUR ROHMAH | C28: 89 | D28: 35 | E28: 80 | F28: 65 | G28: 12 | H28: 11 | I28: 13 | J28: 10 | K28: 11 | L28: 9 | M28: 19 | N28: 15 | O28: 13 | P28: 10 | Q28: 22 | R28: 13 | S28: 10 | T28: 14 | U28: 16 | V28: 9
A29: 21 | B29: NAILA VERDA PUTERI FATHONI | C29: 105 | D29: 35 | E29: 80 | F29: 65 | G29: 13 | H29: 16 | I29: 13 | J29: 15 | K29: 12 | L29: 11 | M29: 13 | N29: 14 | O29: 9 | P29: 11 | Q29: 21 | R29: 17 | S29: 17 | T29: 14 | U29: 5 | V29: 7
A30: 22 | B30: NAJWA NURIL AIN | C30: 115 | D30: 35 | E30: 80 | F30: 35 | G30: 12 | H30: 15 | I30: 9 | J30: 12 | K30: 8 | L30: 9 | M30: 18 | N30: 11 | O30: 16 | P30: 12 | Q30: 20 | R30: 15 | S30: 12 | T30: 12 | U30: 13 | V30: 12
A31: 23 | B31: NAZILA AINI NAZWA | C31: 105 | D31: 35 | E31: 80 | F31: 35 | G31: 14 | H31: 9 | I31: 15 | J31: 15 | K31: 12 | L31: 13 | M31: 6 | N31: 17 | O31: 13 | P31: 15 | Q31: 21 | R31: 15 | S31: 6 | T31: 18 | U31: 3 | V31: 18
A32: 24 | B32: NUR HIDAYATUR RIZQIYAH | C32: 110 | D32: 35 | E32: 80 | F32: 35 | G32: 10 | H32: 15 | I32: 7 | J32: 14 | K32: 12 | L32: 18 | M32: 9 | N32: 13 | O32: 11 | P32: 13 | Q32: 18 | R32: 12 | S32: 15 | T32: 12 | U32: 11 | V32: 15
... A45: 37 | B45: ZAHRIS SHOFIA | C45: 80 | D45: 35 | E45: 80 | F45: 65 | G45: 13 | H45: 16 | I45: 13 | J45: 13 | K45: 9 | L45: 9 | M45: 13 | N45: 16 | O45: 9 | P45: 13 | Q45: 23 | R45: 16 | S45: 15 | T45: 23 | U45: 0 | V45: 7

Sheet BU 2
A3: REKAPITULASI HASIL ASSESMENT
A4: SMK AL MUSYAFFA' KENDAL
A5: KELAS X BU 2
A7: NO | B7: NAMA LENGKAP | C7: IQ | D7: K35AEPLIN | G7: EPP65
D8: 1 | E8: 2 | F8: 3 | G8: 1 | H8: 2 | I8: 3 | J8: 4 | K8: 5 | L8: 6 | M8: 7 | N8: 8 | O8: 9 | P8: 10 | Q8: 11 | R8: 12 | S8: 13 | T8: 14 | U8: 15 | V8: 16
A9: 1 | B9: AIDA FATIMATUZ ZAHRA | C9: 80 | D9: 35 | E9: 80 | F9: 35 | G9: 9 | H9: 11 | I9: 15 | J9: 16 | K9: 14 | L9: 13 | M9: 12 | N9: 13 | O9: 18 | P9: 15 | Q9: 12 | R9: 14 | S9: 19 | T9: 13 | U9: 11 | V9: 15
A10: 2 | B10: ALFINA FUROIDA | C10: 115 | D10: 35 | E10: 80 | F10: 35 | G10: 14 | H10: 14 | I10: 15 | J10: 16 | K10: 10 | L10: 12 | M10: 12 | N10: 13 | O10: 10 | P10: 17 | Q10: 21 | R10: 18 | S10: 11 | T10: 23 | U10: 2 | V10: 16
A11: 3 | B11: ALIFTA HUSNA NATASYA | C11: 115 | D11: 35 | E11: 80 | F11: 35 | G11: 12 | H11: 18 | I11: 10 | J11: 13 | K11: 10 | L11: 7 | M11: 18 | N11: 16 | O11: 19 | P11: 17 | Q11: 23 | R11: 21 | S11: 17 | T11: 18 | U11: 0 | V11: 4
A12: 4 | B12: ANGGI HARYANA PUTRI | C12: 90 | D12: 35 | E12: 80 | F12: 65 | G12: 7 | H12: 13 | I12: 15 | J12: 13 | K12: 15 | L12: 10 | M12: 16 | N12: 22 | O12: 7 | P12: 10 | Q12: 18 | R12: 16 | S12: 23 | T12: 18 | U12: 4 | V12: 8
A13: 5 | B13: ANITA RIZQY CAHYANI | C13: 109 | D13: 35 | E13: 80 | F13: 35 | G13: 9 | H13: 15 | I13: 10 | J13: 14 | K13: 19 | L13: 11 | M13: 13 | N13: 21 | O13: 5 | P13: 13 | Q13: 19 | R13: 13 | S13: 18 | T13: 16 | U13: 10 | V13: 11
A14: 6 | B14: ARIANTI LAILATUL MAGFIROH | C14: 109 | D14: 35 | E14: 80 | F14: 35 | G14: 11 | H14: 10 | I14: 10 | J14: 12 | K14: 19 | L14: 10 | M14: 17 | N14: 20 | O14: 7 | P14: 9 | Q14: 17 | R14: 18 | S14: 18 | T14: 19 | U14: 4 | V14: 18
A15: 7 | B15: ASKA UTU'UL NISA | C15: 80 | D15: 35 | E15: 80 | F15: 35 | G15: 8 | H15: 15 | I15: 14 | J15: 16 | K15: 9 | L15: 11 | M15: 18 | N15: 20 | O15: 14 | P15: 9 | Q15: 18 | R15: 14 | S15: 12 | T15: 18 | U15: 2 | V15: 20
A16: 8 | B16: AULIYA NAJIVA | C16: 89 | D16: 35 | E16: 80 | F16: 35 | G16: 11 | H16: 16 | I16: 12 | J16: 13 | K16: 12 | L16: 18 | M16: 9 | N16: 17 | O16: 15 | P16: 17 | Q16: 22 | R16: 13 | S16: 7 | T16: 11 | U16: 9 | V16: 18
A17: 9 | B17: DESINTA YUMROTUN | C17: 115 | D17: 35 | E17: 80 | F17: 65 | G17: 11 | H17: 14 | I17: 12 | J17: 13 | K17: 13 | L17: 9 | M17: 13 | N17: 19 | O17: 20 | P17: 11 | Q17: 22 | R17: 20 | S17: 15 | T17: 18 | U17: 3 | V17: 5
A18: 10 | B18: DEWI ZAHROH ALMUNAWWAROH | C18: 105 | D18: 35 | E18: 80 | F18: 65 | G18: 9 | H18: 14 | I18: 12 | J18: 17 | K18: 17 | L18: 17 | M18: 14 | N18: 14 | O18: 17 | P18: 10 | Q18: 18 | R18: 16 | S18: 12 | T18: 13 | U18: 4 | V18: 14
A19: 11 | B19: DINA ARIYANI OKTAVIA | C19: 105 | D19: 35 | E19: 80 | F19: 35 | G19: 14 | H19: 13 | I19: 9 | J19: 14 | K19: 16 | L19: 8 | M19: 16 | N19: 16 | O19: 13 | P19: 15 | Q19: 12 | R19: 17 | S19: 23 | T19: 10 | U19: 2 | V19: 26
A20: 12 | B20: DWI AYU MASITA | C20: 85 | D20: 35 | E20: 80 | F20: 65 | G20: 13 | H20: 13 | I20: 15 | J20: 17 | K20: 18 | L20: 10 | M20: 17 | N20: 15 | O20: 16 | P20: 6 | Q20: 21 | R20: 16 | S20: 16 | T20: 18 | U20: 4 | V20: 9
... A44: 36 | B44: ZULFA MALIKATUNNISA | C44: 90 | D44: 35 | E44: 80 | F44: 35 | G44: 8 | H44: 14 | I44: 8 | J44: 9 | K44: 9 | L44: 12 | M44: 18 | N44: 12 | O44: 14 | P44: 14 | Q44: 13 | R44: 21 | S44: 12 | T44: 18 | U44: 12 | V44: 17

Sheet BlankoSertifikat
A1: REKAPITULASI HASIL ASSESMENT
A2: SMK AL MUSYAFFA' - KABUPATEN KENDAL
A3: KELAS X TO 1
B4: Tanggal Tes
B5: 45283
A6: NO | B6: NAMA | C6: L/P | D6: IQ | E6: KINERJA | H6: KEPRIBADIAN | X6: KEMAMPUAN KHUSUS
E7: 1 | F7: 2 | G7: 3 | H7: 1 | I7: 2 | J7: 3 | K7: 4 | L7: 5 | M7: 6 | N7: 7 | O7: 8 | P7: 9 | Q7: 10 | R7: 11 | S7: 12 | T7: 13 | U7: 14 | V7: 15 | W7: 16 | X7: 1 | Y7: 2 | Z7: 3 | AA7: 4 | AB7: 5 | AC7: 6 | AD7: 7 | AE7: 8 | AF7: 9 | AG7: 10 | AH7: 31 | AI7: 32
A8: 1 | B8: AHMAD FARIZQI RIDWAN | D8: 115 | E8: 35 | F8: 35 | G8: 35 | H8: 7 | I8: 11 | J8: 12 | K8: 15 | L8: 12 | M8: 9 | N8: 16 | O8: 12 | P8: 13 | Q8: 10 | R8: 16 | S8: 9 | T8: 14 | U8: 17 | V8: 11 | W8: 16
A9: 2 | B9: AHMAD IDRIS SIREGAR | D9: 85 | E9: 35 | F9: 35 | G9: 35 | H9: 5 | I9: 13 | J9: 10 | K9: 11 | L9: 14 | M9: 11 | N9: 16 | O9: 21 | P9: 11 | Q9: 13 | R9: 12 | S9: 9 | T9: 16 | U9: 13 | V9: 11 | W9: 13
A10: 3 | B10: AHMAD IRFAN | D10: 105 | E10: 35 | F10: 35 | G10: 35 | H10: 10 | I10: 14 | J10: 11 | K10: 15 | L10: 13 | M10: 12 | N10: 10 | O10: 17 | P10: 9 | Q10: 13 | R10: 10 | S10: 11 | T10: 12 | U10: 12 | V10: 18 | W10: 18
A11: 4 | B11: ALIF BUDI FIRMANSYAH | D11: 80 | E11: 35 | F11: 80 | G11: 35 | H11: 9 | I11: 10 | J11: 13 | K11: 12 | L11: 15 | M11: 12 | N11: 14 | O11: 18 | P11: 14 | Q11: 16 | R11: 13 | S11: 11 | T11: 15 | U11: 8 | V11: 11 | W11: 15
A12: 5 | B12: AURA IDRIS AL QODRI | D12: 123 | E12: 35 | F12: 35 | G12: 35 | H12: 8 | I12: 9 | J12: 11 | K12: 12 | L12: 11 | M12: 13 | N12: 18 | O12: 16 | P12: 18 | Q12: 13 | R12: 12 | S12: 15 | T12: 13 | U12: 12 | V12: 10 | W12: 12
A13: 6 | B13: BAYU SAPUTRA | D13: 80 | E13: 35 | F13: 80 | G13: 65 | H13: 5 | I13: 12 | J13: 12 | K13: 14 | L13: 15 | M13: 9 | N13: 13 | O13: 17 | P13: 8 | Q13: 14 | R13: 16 | S13: 12 | T13: 14 | U13: 13 | V13: 11 | W13: 13
A14: 7 | B14: BIMBIM OCTA RAMADHANI | D14: 119 | E14: 35 | F14: 35 | G14: 35 | H14: 9 | I14: 8 | J14: 8 | K14: 9 | L14: 12 | M14: 14 | N14: 11 | O14: 16 | P14: 22 | Q14: 10 | R14: 17 | S14: 14 | T14: 9 | U14: 14 | V14: 15 | W14: 12
A15: 8 | B15: DAVIN AHMAD CHOIRUL YAQIN | D15: 80 | E15: 35 | F15: 80 | G15: 35 | H15: 8 | I15: 12 | J15: 8 | K15: 12 | L15: 10 | M15: 12 | N15: 14 | O15: 13 | P15: 17 | Q15: 11 | R15: 16 | S15: 9 | T15: 14 | U15: 17 | V15: 16 | W15: 12
A16: 9 | B16: ERNEST GERALDINE ARIANCA MAULANA | D16: 125 | E16: 35 | F16: 80 | G16: 35 | H16: 10 | I16: 18 | J16: 7 | K16: 10 | L16: 7 | M16: 10 | N16: 13 | O16: 11 | P16: 15 | Q16: 6 | R16: 20 | S16: 22 | T16: 11 | U16: 23 | V16: 11 | W16: 7
A17: 10 | B17: FARIS NAUFAL NURDIANSYAH | D17: 125 | E17: 65 | F17: 80 | G17: 80 | H17: 6 | I17: 9 | J17: 13 | K17: 16 | L17: 9 | M17: 14 | N17: 13 | O17: 13 | P17: 13 | Q17: 16 | R17: 15 | S17: 15 | T17: 12 | U17: 15 | V17: 10 | W17: 13
A18: 11 | B18: HAIKAL ABDUL GHOFUR | D18: 130 | E18: 35 | F18: 80 | G18: 35 | H18: 8 | I18: 13 | J18: 11 | K18: 14 | L18: 9 | M18: 11 | N18: 18 | O18: 11 | P18: 19 | Q18: 12 | R18: 14 | S18: 12 | T18: 13 | U18: 13 | V18: 16 | W18: 8
A19: 12 | B19: IKMAL MU'IN | D19: 90 | E19: 35 | F19: 80 | G19: 35 | H19: 9 | I19: 13 | J19: 9 | K19: 15 | L19: 13 | M19: 13 | N19: 16 | O19: 11 | P19: 12 | Q19: 17 | R19: 14 | S19: 13 | T19: 8 | U19: 17 | V19: 9 | W19: 16
... A22: 15 | B22: M. HUMAIDULLOH IRFAN | D22: 90 | E22: 35 | F22: 35 | G22: 35 | H22: 11 | I22: 16 | J22: 10 | K22: 13 | L22: 9 | M22: 10 | N22: 12 | O22: 14 | P22: 19 | Q22: 14 | R22: 12 | S22: 18 | T22: 13 | U22: 20 | V22: 9 | W22: 5
A23: 16 | B23: M. SAHRIEL SAPUTRA
A24: 17 | B24: M. WILDAN MUBAROK | D24: 115 | E24: 35 | F24: 35 | G24: 35 | H24: 10 | I24: 10 | J24: 16 | K24: 10 | L24: 10 | M24: 14 | N24: 16 | O24: 9 | P24: 12 | Q24: 15 | R24: 18 | S24: 9 | T24: 9 | U24: 17 | V24: 15 | W24: 13
A25: 18 | B25: MARTHA RIVAN ALFARIZ | D25: 80 | E25: 35 | F25: 35 | G25: 35 | H25: 11 | I25: 17 | J25: 9 | K25: 14 | L25: 16 | M25: 6 | N25: 14 | O25: 12 | P25: 20 | Q25: 10 | R25: 13 | S25: 16 | T25: 19 | U25: 17 | V25: 3 | W25: 9
A26: 19 | B26: MOHAMAD ALFARIJI | D26: 109 | E26: 35 | F26: 35 | G26: 65 | H26: 12 | I26: 13 | J26: 7 | K26: 6 | L26: 14 | M26: 13 | N26: 15 | O26: 14 | P26: 13 | Q26: 10 | R26: 17 | S26: 22 | T26: 10 | U26: 15 | V26: 8 | W26: 16
A27: 20 | B27: MUH. ILHAM FEBRIANSYAH | D27: 89 | E27: 35 | F27: 80 | G27: 35 | H27: 11 | I27: 15 | J27: 10 | K27: 15 | L27: 14 | M27: 10 | N27: 13 | O27: 11 | P27: 15 | Q27: 11 | R27: 14 | S27: 14 | T27: 11 | U27: 13 | V27: 14 | W27: 15
A28: 21 | B28: MUHAMAD ALYAMARI | D28: 110 | E28: 35 | F28: 80 | G28: 35 | H28: 11 | I28: 10 | J28: 10 | K28: 12 | L28: 10 | M28: 12 | N28: 17 | O28: 20 | P28: 17 | Q28: 14 | R28: 18 | S28: 15 | T28: 8 | U28: 16 | V28: 6 | W28: 11
A29: 22 | B29: MUHAMMAD AFFAN FANNANI | D29: 119 | E29: 35 | F29: 35 | G29: 35 | H29: 10 | I29: 15 | J29: 10 | K29: 5 | L29: 13 | M29: 16 | N29: 11 | O29: 13 | P29: 22 | Q29: 10 | R29: 17 | S29: 14 | T29: 13 | U29: 14 | V29: 12 | W29: 10
A30: 23 | B30: MUHAMMAD BAGUS TRIWARSITO | D30: 130 | E30: 35 | F30: 65 | G30: 35 | H30: 10 | I30: 16 | J30: 11 | K30: 10 | L30: 15 | M30: 8 | N30: 13 | O30: 21 | P30: 18 | Q30: 11 | R30: 16 | S30: 12 | T30: 12 | U30: 12 | V30: 7 | W30: 13
A31: 24 | B31: MUHAMMAD DZAKY HAIDAR DAFFA | D31: 85 | E31: 35 | F31: 35 | G31: 35 | H31: 10 | I31: 12 | J31: 4 | K31: 8 | L31: 12 | M31: 11 | N31: 15 | O31: 11 | P31: 22 | Q31: 10 | R31: 25 | S31: 19 | T31: 10 | U31: 14 | V31: 9 | W31: 14
A32: 25 | B32: MUHAMMAD HANIFIL ANAM
A33: 26 | B33: MUHAMMAD IRZAM FAIRUS SAPUTRA | D33: 85 | E33: 35 | F33: 80 | G33: 35 | H33: 7 | I33: 11 | J33: 12 | K33: 15 | L33: 13 | M33: 14 | N33: 9 | O33: 16 | P33: 13 | Q33: 16 | R33: 14 | S33: 10 | T33: 12 | U33: 14 | V33: 14 | W33: 13
A34: 27 | B34: MUHAMMAD RIFQI WIDIANTO | D34: 80 | E34: 35 | F34: 35 | G34: 35 | H34: 7 | I34: 14 | J34: 11 | K34: 9 | L34: 13 | M34: 8 | N34: 13 | O34: 13 | P34: 16 | Q34: 15 | R34: 14 | S34: 15 | T34: 15 | U34: 16 | V34: 10 | W34: 13
A35: 28 | B35: MUHAMMAD SEPTIANO RIZKY RAMADHAN | D35: 109 | E35: 35 | F35: 80 | G35: 35 | H35: 9 | I35: 8 | J35: 8 | K35: 13 | L35: 11 | M35: 11 | N35: 12 | O35: 18 | P35: 13 | Q35: 17 | R35: 16 | S35: 10 | T35: 10 | U35: 15 | V35: 16 | W35: 16
A36: 29 | B36: MUKHAMMAD ADIB | D36: 105 | E36: 35 | F36: 80 | G36: 65 | H36: 6 | I36: 8 | J36: 11 | K36: 12 | L36: 11 | M36: 15 | N36: 12 | O36: 13 | P36: 14 | Q36: 15 | R36: 15 | S36: 7 | T36: 17 | U36: 13 | V36: 18 | W36: 14
A37: 30 | B37: RYAN HIDAYAT | D37: 80 | E37: 35 | F37: 80 | G37: 35 | H37: 9 | I37: 11 | J37: 12 | K37: 15 | L37: 12 | M37: 9 | N37: 16 | O37: 12 | P37: 13 | Q37: 10 | R37: 16 | S37: 9 | T37: 14 | U37: 17 | V37: 11 | W37: 16
A38: 31 | B38: YUDA BAGUS | D38: 80 | E38: 35 | F38: 35 | G38: 35 | H38: 5 | I38: 14 | J38: 10 | K38: 10 | L38: 15 | M38: 9 | N38: 15 | O38: 17 | P38: 13 | Q38: 14 | R38: 11 | S38: 8 | T38: 11 | U38: 17 | V38: 15 | W38: 13
A39: 32 | B39: DINA MAULA ASIFA | D39: 80 | E39: 35 | F39: 35 | G39: 35 | H39: 9 | I39: 10 | J39: 8 | K39: 10 | L39: 15 | M39: 14 | N39: 14 | O39: 12 | P39: 14 | Q39: 11 | R39: 14 | S39: 19 | T39: 14 | U39: 9 | V39: 7 | W39: 18
A40: 33 | B40: ERLINA | D40: 80 | E40: 35 | F40: 80 | G40: 65 | H40: 11 | I40: 16 | J40: 16 | K40: 15 | L40: 8 | M40: 11 | N40: 10 | O40: 18 | P40: 7 | Q40: 11 | R40: 16 | S40: 17 | T40: 17 | U40: 19 | V40: 5 | W40: 8
A41: 34 | B41: HERSA FEMAS ARIS YULIANTO | D41: 80 | E41: 35 | F41: 80 | G41: 35 | H41: 13 | I41: 10 | J41: 10 | K41: 15 | L41: 10 | M41: 14 | N41: 10 | O41: 18 | P41: 10 | Q41: 11 | R41: 13 | S41: 16 | T41: 8 | U41: 19 | V41: 12 | W41: 19
A42: 35 | B42: M. KHOIRUL ZAKI | D42: 80 | E42: 35 | F42: 80 | G42: 35 | H42: 13 | I42: 15 | J42: 14 | K42: 13 | L42: 9 | M42: 12 | N42: 15 | O42: 14 | P42: 14 | Q42: 15 | R42: 15 | S42: 16 | T42: 9 | U42: 16 | V42: 8 | W42: 11
...

Sheet Sertifikat
J1: No | K1: Simbol | L1: IQ | M1: KINERJA | P1: KEMAMPUAN KHUSUS | Y1: KEPRIBADIAN
M2: 2 | N2: 3 | O2: 4 | P2: 5 | Q2: 6 | R2: 7 | S2: 8 | T2: 9 | U2: 10 | V2: 11 | W2: 12 | X2: 13 | Y2: 14 | Z2: 15 | AA2: 16 | AB2: 17 | AC2: 18 | AD2: 19 | AE2: 20 | AF2: 21 | AG2: 22 | AH2: 23 | AI2: 24 | AJ2: 25 | AK2: 26 | AL2: 27 | AM2: 28 | AN2: 29 | AO2: 30 | AP2: 31 | AQ2: 32
J3: 1 | K3: ü | L3: =VLOOKUP(J3,BlankoSertifikat!A:D,4,0) -> 115 | M3: =VLOOKUP(J3,BlankoSertifikat!A:E,5,0) -> 35 | N3: =VLOOKUP(J3,BlankoSertifikat!A:F,6,0) -> 35 | O3: =VLOOKUP(J3,BlankoSertifikat!A:G,7,0) -> 35 | P3: =VLOOKUP(J3,BlankoSertifikat!A:H,8,0) -> 7 | Q3: =VLOOKUP(J3,BlankoSertifikat!A:I,9,0) -> 11 | R3: =VLOOKUP(J3,BlankoSertifikat!A:J,10,0) -> 12 | S3: =VLOOKUP(J3,BlankoSertifikat!A:K,11,0) -> 15 | T3: =VLOOKUP(J3,BlankoSertifikat!A:L,12,0) -> 12 | U3: =VLOOKUP(J3,BlankoSertifikat!A:M,13,0) -> 9 | V3: =VLOOKUP(J3,BlankoSertifikat!A:P,14,0) -> 16 | W3: =VLOOKUP(J3,BlankoSertifikat!A:O,15,0) -> 12 | X3: =VLOOKUP(J3,BlankoSertifikat!A:P,16,0) -> 13 | Y3: =VLOOKUP(J3,BlankoSertifikat!A:Q,17,0) -> 10 | Z3: =VLOOKUP(J3,BlankoSertifikat!A:R,18,0) -> 16 | AA3: =VLOOKUP(J3,BlankoSertifikat!A:S,19,0) -> 9 | AB3: =VLOOKUP(J3,BlankoSertifikat!A:T,20,0) -> 14 | AC3: =VLOOKUP(J3,BlankoSertifikat!A:U,21,0) -> 17 | AD3: =VLOOKUP(J3,BlankoSertifikat!A:V,22,0) -> 11 | AE3: =VLOOKUP(J3,BlankoSertifikat!A:X,23,0) -> 16 | AF3: =VLOOKUP(J3,BlankoSertifikat!A:X,24,0) -> 0 | AG3: =VLOOKUP(J3,BlankoSertifikat!A:Y,25,0) -> 0 | AH3: =VLOOKUP(J3,BlankoSertifikat!A:Z,26,0) -> 0 | AI3: =VLOOKUP(J3,BlankoSertifikat!A:AA,27,0) -> 0 | AJ3: =VLOOKUP(J3,BlankoSertifikat!A:AB,28,0) -> 0 | AK3: =VLOOKUP(J3,BlankoSertifikat!A:AD,29,0) -> 0 | AL3: =VLOOKUP(J3,BlankoSertifikat!A:AD,30,0) -> 0 | AM3: =VLOOKUP(J3,BlankoSertifikat!A:AE,31,0) -> 0 | AN3: =VLOOKUP(J3,BlankoSertifikat!A:AF,32,0) -> 0 | AO3: =VLOOKUP(J3,BlankoSertifikat!A:AG,33,0) -> 0 | AP3: =VLOOKUP(J3,BlankoSertifikat!A:AH,34,0) -> 0 | AQ3: =VLOOKUP(J3,BlankoSertifikat!A:AI,35,0) -> 0
A11: HASIL TES PSIKOLOGI
A13: Nama | B13: : | C13: =VLOOKUP(J3,BlankoSertifikat!A:B,2,0) -> AHMAD FARIZQI RIDWAN | L13: 1. Intlegen | W13: 2. kinerja
A14: Kelas | B14: : | C14: X TO 1 | G14: Tanggal Tes | I14: =BlankoSertifikat!B5 -> 45283 | L14: Ananda memiliki kecerdasan superior (130), | W14: kecenderungan kecepatan kerja cukup tinggi, | AH14: (80
A15: Sekolah | B15: : | C15: SMK AL MUSYAFFA' KENDAL | L15: Ananda memiliki kecerdasan superior (125), | W15: kecenderungan kecepatan kerja sedang, | AH15: (65-79)
L16: Ananda memiliki kecerdasan superior (123), | W16: kecenderungan kecepatan kerja rendah, | AH16: (35-64)
A17: Intelegence | B17: : | C17: Jenis Tes | E17: IQ | G17: Klasifikasi | L17: Ananda memiliki kecerdasan superior (123), | W17: kecenderungan ketelitian kerja cukup tinggi, | AH17: (80
C18: CFIT | E18: =L3 -> 115 | G18: =IF(E18>=170,"Genius",IF(E18>=140,"Sangat Superior",IF(E18>=120,"Superior",IF(E18>=110,"Di atas rata-rata",IF(E18>=90,"Rata-rata",IF(E18>=80,"Di bawah rata-rata",IF(E18>=70,"BEXHerline",IF(E18>=30,"Defektif secara mental","Tidak terklasifikasi")))))))) -> Di atas rata-rata | L18: Ananda memiliki kecerdasan di atas rata-rata (119), | W18: kecenderungan ketelitian kerja sedang, | AH18: (65-79)
L19: Ananda memiliki kecerdasan di atas rata-rata (115), | W19: kecenderungan ketelitian kerja rendah, | AH19: (35-64)
A20: ASPEK YANG DIUNGKAP | C20: KLASIFIKASI | L20: Ananda memiliki kecerdasan di atas rata-rata (110), | W20: kecenderungan ketahanan kerja cukup tinggi, | AH20: (80
C21: RS | D21: R | E21: AR | F21: S | G21: CT | H21: T | I21: TS | L21: Ananda memiliki kecerdasan rata-rata (109), | W21: kecenderungan ketahanan kerja sedang, | AH21: (65-79)
A22: KECEPATAN KERJA | D22: =IF(AND(M3>=35,M3<=64), K3," ") -> ü | F22: =IF(AND(M3>=65,M3<=79), K3," ") | G22: =IF(AND(M3>=80,M3<=100), K3," ") | H22: =IF(AND(M2>=65,M2<=79), K3," ") | J22: 1 | L22: Ananda memiliki kecerdasan rata-rata (105), | W22: kecenderungan ketahanan kerja rendah, | AH22: (35-64)
A23: KETELITIAN KERJA | D23: =IF(AND(N3>=35,N3<=64), K3," ") -> ü | F23: =IF(AND(N3>=65,N3<=79), K3," ") | G23: =IF(AND(N3>=80,N3<=100), K3," ") | J23: 2 | L23: Ananda memiliki kecerdasan rata-rata (90),
A24: KETAHANAN KERJA | D24: =IF(AND(O3>=35,O3<=64), K3," ") -> ü | F24: =IF(AND(O3>=65,O3<=79), K3," ") | G24: =IF(AND(O3>=80,O3<=100), K3," ") | J24: 3 | L24: Ananda memiliki kecerdasan di bawah rata-rata (89), | W24: 3. KEJUJURAN
A25: KEJUJURAN | F25: =IF(AND(P3>=9,P3<=11), K3," ") | G25: =IF(AND(P3>=12,P3<=13), K3," ") | H25: =IF(AND(3>=14,P3<=15), K3," ") | J25: 0 | L25: Ananda memiliki kecerdasan di bawah rata-rata (85), | W25: Ananda memiliki kejujuran tinggi, | AH25: (14-15)
A26: ACHIEVEMENT | C26: =IF(AND(Q11>=1,Q3<=7), K3," ") | D26: =IF(AND(Q3>=8,Q3<=11), K3," ") -> ü | E26: =IF(AND(Q3>=12,Q3<=14), K3," ") | F26: =IF(AND(Q3>=15,Q3<=18), K3," ") | G26: =IF(AND(Q3>=19,Q3<=21), K3," ") | H26: =IF(AND(Q3>=22,Q3<=25), K3," ") | I26: =IF(AND(Q3>=26,Q3<=28), K3," ") | J26: 1 | L26: Ananda memiliki kecerdasan di bawah rata-rata (80), | W26: Ananda memiliki kejujuran cukup tinggi, | AH26: (12-13)
A27: DEFERENCE | C27: =IF(AND(R3>=0,R3<=7), K3," ") | D27: =IF(AND(R3>=8,R3<=10), K3," ") | E27: =IF(AND(R3>=11,R3<=13), K3," ") -> ü | F27: =IF(AND(R3>=14,R3<=16), K3," ") | G27: =IF(AND(R3>=17,R3<=20), K3," ") | H27: =IF(AND(R3>=21,R3<=23), K3," ") | I27: =IF(AND(R3=23,R3<=26), K3," ") | J27: 2 | W27: Ananda memiliki kejujuran sedang, | AH27: (9-11)
A28: ORDER | C28: =IF(AND(S3>=0,S3<=4), K3," ") | D28: =IF(AND(S3>=5,S3<=9), K3," ") | E28: =IF(AND(S3>=10,S3<=14), K3," ") | F28: =IF(AND(S3>=15,S3<=19), K3," ") -> ü | G28: =IF(AND(S3>=20,S3<=24), K3," ") | H28: =IF(AND(S3>=25,S3<=28), K3," ") | J28: 3
A29: EXHIBITION | C29: =IF(AND(T3>=0,T3<=0), K3," ") | D29: =IF(AND(T3>=1,T3<=3), K3," ") | E29: =IF(AND(T3>=4,T3<=7), K3," ") | F29: =IF(AND(T3>=8,T3<=10), K3," ") | G29: =IF(AND(T3>=11,T3<=13), K3," ") -> ü | H29: =IF(AND(T3>=14,T3<=16), K3," ") | I29: =IF(AND(T3>=17,T3<=20), K3," ") | J29: 4
A30: AUTONOMY | C30: =IF(AND(U3>=0,U3<=0), K3," ") | D30: =IF(AND(U3>=2,U3<=0), K3," ") | E30: =IF(AND(U3>=3,U3<=5), K3," ") | F30: =IF(AND(U3>=6,U3<=9), K3," ") -> ü | G30: =IF(AND(U3>=10,U3<=12), K3," ") | H30: =IF(AND(U3>=13,U3<=15), K3," ") | I30: =IF(AND(U3>=16,U3<=19), K3," ") | J30: 5 | L30: 1. Aspek Achievement | R30: 2. Aspek DEF | X30: 3. Aspek ORD | AD30: 4. Aspek EXH | AJ30: 5. Aspek AUT | AP30: 6. Aspek AFF | AV30: 7. Aspek INT
A31: AFFILIATION | C31: =IF(AND(V3>=0,V3<=2), K3," ") | D31: =IF(AND(V3>=3,V3<=6), K3," ") | E31: =IF(AND(V3>=7,V3<=10), K3," ") | F31: =IF(AND(V3>=11,V3<=14), K3," ") | G31: =IF(AND(V3>=15,V3<=18), K3," ") -> ü | H31: =IF(AND(V3>=19,V3<=22), K3," ") | I31: =IF(AND(V3>=23,V3<=25), K3," ") | J31: 6 | L31: Range | M31: Keterangan | R31: Range | S31: Keterangan | X31: Range | Y31: Keterangan | AD31: Range | AE31: Keterangan | AJ31: Range | AK31: Keterangan | AP31: Range | AQ31: Keterangan | AV31: Range | AW31: Keterangan
A32: INTRACEPTION | C32: =IF(AND(W3>=0,W3<=4), K3," ") | D32: =IF(AND(W3>=5,W3<=9), K3," ") | E32: =IF(AND(W3>=10,W3<=13), K3," ") -> ü | F32: =IF(AND(W3>=14,W3<=18), K3," ") | G32: =IF(AND(W3>=19,W3<=22), K3," ") | H32: =IF(AND(W3>=23,W3<=28), K3," ") | J32: 7 | L32: 26 - 28 | M32: Achievement tinggi sekali, | R32: 24 - 26 | S32: Deference tinggi sekali, | Y32: Order tinggi sekali, | AD32: 17 - 20 | AE32: Exhibition tinggi sekali, | AJ32: 16-19 | AK32: Autonomy tinggi sekali, | AP32: 23-25 | AQ32: Affiliation tinggi sekali, | AW32: Intraception tinggi sekali,
A33: SUCCORANCE | C33: =IF(AND(X3>=0,X3<=0), K3," ") | D33: =IF(AND(X3>=1,X3<=3), 3," ") | E33: =IF(AND(X3>=4,X3<=7), K3," ") | F33: =IF(AND(X3>=8,X3<=11), K3," ") | G33: =IF(AND(X3>=12,X3<=15), K3," ") -> ü | H33: =IF(AND(X3>=16,X3<=18), K3," ") | I33: =IF(AND(X3>=19,X3<=22), K3," ") | J33: 8 | L33: 22 - 25 | M33: Achievement tinggi, | R33: 21 - 23 | S33: Deference tinggi, | X33: 25 - 28 | Y33: Order tinggi, | AD33: 14-16 | AE33: Exhibition tinggi, | AJ33: 13-15 | AK33: Autonomy tinggi, | AP33: 19-22 | AQ33: Affiliation tinggi, | AV33: 23-28 | AW33: Intraception tinggi,
A34: DOMINANCE | C34: =IF(AND(Y3>=0,Y3<=5), K3," ") | D34: =IF(AND(Y3>=6,Y3<=10), K3," ") -> ü | E34: =IF(AND(Y3>=11,Y3<=14), K3," ") | F34: =IF(AND(Y3>=15,Y3<=18), K3," ") | G34: =IF(AND(Y3>=19,Y3<=22), K3," ") | H34: =IF(AND(Y3>=23,Y3<=26), K3," ") | I34: =IF(AND(Y3>=27,Y3<=28), K3," ") | J34: 9 | L34: 19 - 21 | M34: Achievement cukup tinggi, | R34: 17 - 20 | S34: Deference cukup tinggi, | X34: 20 - 24 | Y34: Order cukup tinggi, | AD34: 11 - 13 | AE34: Exhibition cukup tinggi, | AJ34: 10-12 | AK34: Autonomy cukup tinggi, | AP34: 15-19 | AQ34: Affiliation cukup tinggi, | AV34: 19 - 22 | AW34: Intraception cukup tinggi,
A35: ABASEMENT | C35: =IF(AND(Z3>=0,Z3<=6), K3," ") | D35: =IF(AND(Z3>=7,Z3<=11), K3," ") | E35: =IF(AND(Z3>=12,Z3<=16), K3," ") -> ü | F35: =IF(AND(Z3>=17,Z3<=20), K3," ") | G35: =IF(AND(Z3>=21,Z3<=25), K3," ") | H35: =IF(AND(Z3>=26,Z3<=28), K3," ") | J35: 10 | L35: 15 - 18 | M35: Achievement sedang, | R35: 14 - 16 | S35: Deference sedang, | X35: 15 - 19 | Y35: Order sedang, | AD35: 8-10 | AE35: Exhibition sedang, | AJ35: 6-9 | AK35: Autonomy sedang, | AP35: 11-14 | AQ35: Affiliation sedang, | AV35: 14-18 | AW35: Intraception sedang,
A36: NURTURANCE | C36: =IF(AND(AA3>=0,AA3<=7), K3," ") | D36: =IF(AND(AA3>=8,AA3<=12), K3," ") -> ü | E36: =IF(AND(AA3>=13,AA3<=16), K3," ") | F36: =IF(AND(AA3>=17,AA3<=20), K3," ") | G36: =IF(AND(AA3>=21,AA3<=25), K3," ") | H36: =IF(AND(AA3>=26,AA3<=28), K3," ") | J36: 11 | L36: 12 - 14 | M36: Achievement amat rendah, | R36: 11 - 13 | S36: Deference amat rendah, | X36: 10 - 14 | Y36: Order amat rendah, | AD36: 4 - 7 | AE36: Exhibition amat rendah, | AJ36: 3 - 5 | AK36: Aautonomy amat rendah, | AP36: 7-10 | AQ36: Affiliation amat rendah, | AV36: 10-13 | AW36: Intraception amat rendah,
